2017-12-29 17:25:23,723 [Thread-2:139912664262400] [django.request:170] [base:get_response] [WARNING]- Not Found: /
2017-12-30 16:47:15,181 [Thread-7:140704068138752] [django.request:170] [base:get_response] [WARNING]- Not Found: /quantization/index/js/classie.js
2017-12-30 16:47:30,636 [Thread-13:140704293947136] [django.request:170] [base:get_response] [WARNING]- Not Found: /quantization/index/js/classie.js
2017-12-30 16:48:48,402 [Thread-19:140704293947136] [django.request:170] [base:get_response] [WARNING]- Not Found: /quantization/index/js/classie.js
2017-12-30 16:48:51,848 [Thread-25:140704068138752] [django.request:170] [base:get_response] [WARNING]- Not Found: /quantization/index/js/classie.js
2017-12-30 16:49:21,505 [Thread-31:140704068138752] [django.request:170] [base:get_response] [WARNING]- Not Found: /quantization/index/js/classie.js
2017-12-30 16:55:17,873 [Thread-37:140704285554432] [django.request:170] [base:get_response] [WARNING]- Not Found: /quantization/index/js/classie.js
2017-12-30 16:58:49,840 [Thread-43:140704068138752] [django.request:170] [base:get_response] [WARNING]- Not Found: /quantization/index/js/classie.js
2017-12-30 17:01:09,141 [Thread-49:140704285554432] [django.request:170] [base:get_response] [WARNING]- Not Found: /quantization/index/js/classie.js
2017-12-30 17:01:10,492 [Thread-56:140704285554432] [django.request:170] [base:get_response] [WARNING]- Not Found: /quantization/index/js/classie.js
2017-12-30 17:01:30,836 [Thread-58:140704285554432] [django.request:170] [base:get_response] [WARNING]- Not Found: /favicon.ico
2017-12-30 17:01:33,361 [Thread-63:140704059746048] [django.request:170] [base:get_response] [WARNING]- Not Found: /quantization/index/js/classie.js
2017-12-30 17:01:33,985 [Thread-65:140704059746048] [django.request:170] [base:get_response] [WARNING]- Not Found: /favicon.ico
2017-12-30 17:03:10,791 [Thread-87:140704068138752] [django.request:170] [base:get_response] [WARNING]- Not Found: /favicon.ico
2017-12-30 17:03:47,122 [Thread-102:140704293947136] [django.request:170] [base:get_response] [WARNING]- Not Found: /favicon.ico
2017-12-30 17:03:47,619 [Thread-110:140704304789248] [django.request:170] [base:get_response] [WARNING]- Not Found: /favicon.ico
2017-12-30 17:03:47,783 [Thread-118:140704051353344] [django.request:170] [base:get_response] [WARNING]- Not Found: /favicon.ico
2017-12-30 17:03:48,631 [Thread-126:140704068138752] [django.request:170] [base:get_response] [WARNING]- Not Found: /favicon.ico
2017-12-30 17:04:02,872 [Thread-9:140013356136192] [django.request:170] [base:get_response] [WARNING]- Not Found: /favicon.ico
2017-12-30 17:04:04,194 [Thread-17:140012964271872] [django.request:170] [base:get_response] [WARNING]- Not Found: /favicon.ico
2017-12-30 17:04:04,791 [Thread-25:140013347743488] [django.request:170] [base:get_response] [WARNING]- Not Found: /favicon.ico
2017-12-30 17:04:05,266 [Thread-33:140013356136192] [django.request:170] [base:get_response] [WARNING]- Not Found: /favicon.ico
2017-12-30 17:04:05,672 [Thread-41:140013347743488] [django.request:170] [base:get_response] [WARNING]- Not Found: /favicon.ico
2017-12-30 17:04:06,146 [Thread-49:140012964271872] [django.request:170] [base:get_response] [WARNING]- Not Found: /favicon.ico
2017-12-30 17:04:12,461 [Thread-60:140013339088640] [django.request:170] [base:get_response] [WARNING]- Not Found: /favicon.ico
2017-12-30 17:04:13,670 [Thread-68:140013339088640] [django.request:170] [base:get_response] [WARNING]- Not Found: /favicon.ico
2017-12-30 17:04:13,917 [Thread-76:140013339088640] [django.request:170] [base:get_response] [WARNING]- Not Found: /favicon.ico
2017-12-30 17:04:14,111 [Thread-84:140013356136192] [django.request:170] [base:get_response] [WARNING]- Not Found: /favicon.ico
2017-12-30 17:04:14,302 [Thread-92:140013347743488] [django.request:170] [base:get_response] [WARNING]- Not Found: /favicon.ico
2017-12-30 17:04:14,440 [Thread-100:140013347743488] [django.request:170] [base:get_response] [WARNING]- Not Found: /favicon.ico
2017-12-30 17:04:14,612 [Thread-108:140012964271872] [django.request:170] [base:get_response] [WARNING]- Not Found: /favicon.ico
2017-12-30 17:04:15,209 [Thread-116:140013347743488] [django.request:170] [base:get_response] [WARNING]- Not Found: /favicon.ico
2017-12-30 17:04:15,502 [Thread-124:140012981057280] [django.request:170] [base:get_response] [WARNING]- Not Found: /favicon.ico
2017-12-30 17:04:15,710 [Thread-132:140012964271872] [django.request:170] [base:get_response] [WARNING]- Not Found: /favicon.ico
2017-12-30 17:04:15,914 [Thread-140:140013339088640] [django.request:170] [base:get_response] [WARNING]- Not Found: /favicon.ico
2017-12-30 17:04:45,996 [Thread-155:140013356136192] [django.request:170] [base:get_response] [WARNING]- Not Found: /favicon.ico
2017-12-30 17:04:47,144 [Thread-163:140013347743488] [django.request:170] [base:get_response] [WARNING]- Not Found: /favicon.ico
2017-12-30 17:05:01,203 [Thread-171:140012972664576] [django.request:170] [base:get_response] [WARNING]- Not Found: /favicon.ico
2017-12-30 17:05:51,350 [Thread-186:140012981057280] [django.request:170] [base:get_response] [WARNING]- Not Found: /favicon.ico
2017-12-30 17:05:51,961 [Thread-194:140013347743488] [django.request:170] [base:get_response] [WARNING]- Not Found: /favicon.ico
2017-12-30 17:06:14,210 [Thread-217:140012972664576] [django.request:170] [base:get_response] [WARNING]- Not Found: /favicon.ico
2017-12-30 23:06:38,226 [Thread-492:139687352063744] [django.request:170] [base:get_response] [WARNING]- Not Found: /favicon.ico
2017-12-30 23:06:39,082 [Thread-496:139687343671040] [django.request:170] [base:get_response] [WARNING]- Not Found: /favicon.ico
2017-12-31 09:26:16,455 [Thread-696:139687368849152] [django.request:170] [base:get_response] [WARNING]- Not Found: /favicon.ico
2017-12-31 22:34:10,093 [Thread-369:140655659104000] [django.request:170] [base:get_response] [WARNING]- Not Found: /gg_bd_ad_720x90.js
2017-12-31 22:34:10,096 [Thread-370:140655650711296] [django.request:170] [base:get_response] [WARNING]- Not Found: /follow.js
2017-12-31 22:37:38,544 [Thread-375:140655659104000] [django.request:170] [base:get_response] [WARNING]- Not Found: /gg_bd_ad_720x90.js
2017-12-31 22:37:38,552 [Thread-376:140655642318592] [django.request:170] [base:get_response] [WARNING]- Not Found: /follow.js
2017-12-31 22:40:01,503 [Thread-399:140655670208256] [django.request:170] [base:get_response] [WARNING]- Not Found: /gg_bd_ad_720x90.js
2017-12-31 22:40:01,521 [Thread-400:140655650711296] [django.request:170] [base:get_response] [WARNING]- Not Found: /follow.js
2017-12-31 22:40:04,377 [Thread-405:140655659104000] [django.request:170] [base:get_response] [WARNING]- Not Found: /gg_bd_ad_720x90.js
2017-12-31 22:40:04,388 [Thread-406:140655642318592] [django.request:170] [base:get_response] [WARNING]- Not Found: /follow.js
2018-01-01 10:14:56,483 [Thread-752:140655659104000] [django.request:170] [base:get_response] [WARNING]- Not Found: /quantization/income/
2018-01-01 10:15:26,087 [Thread-2:140331177735936] [django.request:256] [base:handle_uncaught_exception] [ERROR]- Internal Server Error: /quantization/income/
Traceback (most recent call last):
  File "/root/.virtualenvs/student/lib/python3.5/site-packages/django/core/urlresolvers.py", line 394, in urlconf_module
    return self._urlconf_module
AttributeError: 'RegexURLResolver' object has no attribute '_urlconf_module'

During handling of the above exception, another exception occurred:

Traceback (most recent call last):
  File "/root/.virtualenvs/student/lib/python3.5/site-packages/django/core/handlers/base.py", line 119, in get_response
    resolver_match = resolver.resolve(request.path_info)
  File "/root/.virtualenvs/student/lib/python3.5/site-packages/django/core/urlresolvers.py", line 366, in resolve
    for pattern in self.url_patterns:
  File "/root/.virtualenvs/student/lib/python3.5/site-packages/django/core/urlresolvers.py", line 402, in url_patterns
    patterns = getattr(self.urlconf_module, "urlpatterns", self.urlconf_module)
  File "/root/.virtualenvs/student/lib/python3.5/site-packages/django/core/urlresolvers.py", line 396, in urlconf_module
    self._urlconf_module = import_module(self.urlconf_name)
  File "/root/.virtualenvs/student/lib/python3.5/importlib/__init__.py", line 126, in import_module
    return _bootstrap._gcd_import(name[level:], package, level)
  File "<frozen importlib._bootstrap>", line 986, in _gcd_import
  File "<frozen importlib._bootstrap>", line 969, in _find_and_load
  File "<frozen importlib._bootstrap>", line 958, in _find_and_load_unlocked
  File "<frozen importlib._bootstrap>", line 673, in _load_unlocked
  File "<frozen importlib._bootstrap_external>", line 665, in exec_module
  File "<frozen importlib._bootstrap>", line 222, in _call_with_frames_removed
  File "/root/student/student/urls.py", line 21, in <module>
    url(r'^quantization/', include('quantization.urls', namespace='quantization')),
  File "/root/.virtualenvs/student/lib/python3.5/site-packages/django/conf/urls/__init__.py", line 33, in include
    urlconf_module = import_module(urlconf_module)
  File "/root/.virtualenvs/student/lib/python3.5/importlib/__init__.py", line 126, in import_module
    return _bootstrap._gcd_import(name[level:], package, level)
  File "<frozen importlib._bootstrap>", line 986, in _gcd_import
  File "<frozen importlib._bootstrap>", line 969, in _find_and_load
  File "<frozen importlib._bootstrap>", line 958, in _find_and_load_unlocked
  File "<frozen importlib._bootstrap>", line 673, in _load_unlocked
  File "<frozen importlib._bootstrap_external>", line 665, in exec_module
  File "<frozen importlib._bootstrap>", line 222, in _call_with_frames_removed
  File "/root/student/quantization/urls.py", line 32, in <module>
    url(r'^income/$', views.income, name='income'),
AttributeError: module 'quantization.views' has no attribute 'income'
2018-01-01 10:15:34,040 [Thread-3:140331177735936] [django.request:256] [base:handle_uncaught_exception] [ERROR]- Internal Server Error: /quantization/income/
Traceback (most recent call last):
  File "/root/.virtualenvs/student/lib/python3.5/site-packages/django/core/urlresolvers.py", line 394, in urlconf_module
    return self._urlconf_module
AttributeError: 'RegexURLResolver' object has no attribute '_urlconf_module'

During handling of the above exception, another exception occurred:

Traceback (most recent call last):
  File "/root/.virtualenvs/student/lib/python3.5/site-packages/django/core/handlers/base.py", line 119, in get_response
    resolver_match = resolver.resolve(request.path_info)
  File "/root/.virtualenvs/student/lib/python3.5/site-packages/django/core/urlresolvers.py", line 366, in resolve
    for pattern in self.url_patterns:
  File "/root/.virtualenvs/student/lib/python3.5/site-packages/django/core/urlresolvers.py", line 402, in url_patterns
    patterns = getattr(self.urlconf_module, "urlpatterns", self.urlconf_module)
  File "/root/.virtualenvs/student/lib/python3.5/site-packages/django/core/urlresolvers.py", line 396, in urlconf_module
    self._urlconf_module = import_module(self.urlconf_name)
  File "/root/.virtualenvs/student/lib/python3.5/importlib/__init__.py", line 126, in import_module
    return _bootstrap._gcd_import(name[level:], package, level)
  File "<frozen importlib._bootstrap>", line 986, in _gcd_import
  File "<frozen importlib._bootstrap>", line 969, in _find_and_load
  File "<frozen importlib._bootstrap>", line 958, in _find_and_load_unlocked
  File "<frozen importlib._bootstrap>", line 673, in _load_unlocked
  File "<frozen importlib._bootstrap_external>", line 665, in exec_module
  File "<frozen importlib._bootstrap>", line 222, in _call_with_frames_removed
  File "/root/student/student/urls.py", line 21, in <module>
    url(r'^quantization/', include('quantization.urls', namespace='quantization')),
  File "/root/.virtualenvs/student/lib/python3.5/site-packages/django/conf/urls/__init__.py", line 33, in include
    urlconf_module = import_module(urlconf_module)
  File "/root/.virtualenvs/student/lib/python3.5/importlib/__init__.py", line 126, in import_module
    return _bootstrap._gcd_import(name[level:], package, level)
  File "<frozen importlib._bootstrap>", line 986, in _gcd_import
  File "<frozen importlib._bootstrap>", line 969, in _find_and_load
  File "<frozen importlib._bootstrap>", line 958, in _find_and_load_unlocked
  File "<frozen importlib._bootstrap>", line 673, in _load_unlocked
  File "<frozen importlib._bootstrap_external>", line 665, in exec_module
  File "<frozen importlib._bootstrap>", line 222, in _call_with_frames_removed
  File "/root/student/quantization/urls.py", line 32, in <module>
    url(r'^income/$', views.income, name='income'),
AttributeError: module 'quantization.views' has no attribute 'income'
2018-01-01 14:53:45,970 [Thread-575:140583184918272] [django.request:170] [base:get_response] [WARNING]- Not Found: /quantization/city/css/style.css
2018-01-01 15:39:37,424 [Thread-613:139959486899968] [django.request:170] [base:get_response] [WARNING]- Not Found: /quantization/city/css/ydui.css
2018-01-01 15:39:37,428 [Thread-614:139959578924800] [django.request:170] [base:get_response] [WARNING]- Not Found: /quantization/city/css/demo.css
2018-01-01 15:39:37,437 [Thread-615:139959470114560] [django.request:170] [base:get_response] [WARNING]- Not Found: /quantization/city/js/ydui.flexible.js
2018-01-01 15:39:37,443 [Thread-616:139959478507264] [django.request:170] [base:get_response] [WARNING]- Not Found: /quantization/city/js/jquery.min.js
2018-01-01 15:39:37,450 [Thread-617:139959578924800] [django.request:170] [base:get_response] [WARNING]- Not Found: /quantization/city/js/ydui.citys.js
2018-01-01 15:39:37,461 [Thread-618:139959486899968] [django.request:170] [base:get_response] [WARNING]- Not Found: /quantization/city/js/ydui.js
2018-01-01 15:39:37,475 [Thread-619:139959486899968] [django.request:170] [base:get_response] [WARNING]- Not Found: /quantization/city/js/ydui.citys.js
2018-01-01 15:39:37,497 [Thread-620:139959486899968] [django.request:170] [base:get_response] [WARNING]- Not Found: /quantization/city/js/ydui.js
2018-01-01 15:39:43,040 [Thread-622:139959486899968] [django.request:170] [base:get_response] [WARNING]- Not Found: /quantization/city/css/ydui.css
2018-01-01 15:39:43,053 [Thread-623:139959578924800] [django.request:170] [base:get_response] [WARNING]- Not Found: /quantization/city/css/demo.css
2018-01-01 15:39:43,058 [Thread-624:139959486899968] [django.request:170] [base:get_response] [WARNING]- Not Found: /quantization/city/js/ydui.flexible.js
2018-01-01 15:39:43,073 [Thread-625:139959478507264] [django.request:170] [base:get_response] [WARNING]- Not Found: /quantization/city/js/jquery.min.js
2018-01-01 15:39:43,079 [Thread-626:139959486899968] [django.request:170] [base:get_response] [WARNING]- Not Found: /quantization/city/js/ydui.citys.js
2018-01-01 15:39:43,085 [Thread-627:139959578924800] [django.request:170] [base:get_response] [WARNING]- Not Found: /quantization/city/js/ydui.js
2018-01-01 15:56:29,596 [Thread-1276:139959478507264] [django.request:170] [base:get_response] [WARNING]- Not Found: /favicon.ico
2018-01-01 15:56:37,606 [Thread-1291:139959470114560] [django.request:170] [base:get_response] [WARNING]- Not Found: /favicon.ico
2018-01-01 15:57:33,518 [Thread-1307:139959470114560] [django.request:170] [base:get_response] [WARNING]- Not Found: /favicon.ico
2018-01-01 16:05:59,005 [Thread-1582:139959486899968] [django.request:170] [base:get_response] [WARNING]- Not Found: /quantization/income/mymod.js
2018-01-01 16:06:15,419 [Thread-1599:139959486899968] [django.request:170] [base:get_response] [WARNING]- Not Found: /quantization/income/mymod.js
2018-01-01 16:27:37,489 [Thread-2151:139959495292672] [django.request:170] [base:get_response] [WARNING]- Not Found: /favicon.ico
2018-01-01 16:28:08,360 [Thread-2180:139959470114560] [django.request:170] [base:get_response] [WARNING]- Not Found: /favicon.ico
2018-01-01 16:30:27,195 [Thread-2215:139959578924800] [django.request:170] [base:get_response] [WARNING]- Not Found: /favicon.ico
2018-01-01 16:32:00,592 [Thread-2261:139959486899968] [django.request:170] [base:get_response] [WARNING]- Not Found: /favicon.ico
2018-01-01 16:33:21,467 [Thread-2312:139959470114560] [django.request:170] [base:get_response] [WARNING]- Not Found: /favicon.ico
2018-01-01 16:33:59,653 [Thread-2346:139959461721856] [django.request:170] [base:get_response] [WARNING]- Not Found: /favicon.ico
2018-01-01 16:34:43,492 [Thread-2377:139959470114560] [django.request:170] [base:get_response] [WARNING]- Not Found: /favicon.ico
2018-01-01 16:35:44,564 [Thread-2417:139959478507264] [django.request:170] [base:get_response] [WARNING]- Not Found: /favicon.ico
2018-01-01 16:38:13,426 [Thread-2467:139959461721856] [django.request:170] [base:get_response] [WARNING]- Not Found: /favicon.ico
2018-01-01 16:41:14,011 [Thread-2498:139959578924800] [django.request:170] [base:get_response] [WARNING]- Not Found: /favicon.ico
2018-01-01 16:45:13,576 [Thread-2546:139959486899968] [django.request:170] [base:get_response] [WARNING]- Not Found: /favicon.ico
2018-01-01 16:51:46,331 [Thread-2743:139959461721856] [django.request:170] [base:get_response] [WARNING]- Not Found: /favicon.ico
2018-01-01 17:29:22,088 [Thread-2844:139959486899968] [django.request:170] [base:get_response] [WARNING]- Not Found: /favicon.ico
2018-01-01 17:30:14,419 [Thread-2863:139959578924800] [django.request:170] [base:get_response] [WARNING]- Not Found: /favicon.ico
2018-01-01 17:30:15,367 [Thread-2882:139959461721856] [django.request:170] [base:get_response] [WARNING]- Not Found: /favicon.ico
2018-01-01 17:30:35,823 [Thread-2902:139959578924800] [django.request:170] [base:get_response] [WARNING]- Not Found: /favicon.ico
2018-01-01 17:30:46,703 [Thread-2921:139959461721856] [django.request:170] [base:get_response] [WARNING]- Not Found: /favicon.ico
2018-01-01 17:32:36,289 [Thread-2940:139959495292672] [django.request:170] [base:get_response] [WARNING]- Not Found: /favicon.ico
2018-01-01 17:33:07,940 [Thread-2961:139959470114560] [django.request:170] [base:get_response] [WARNING]- Not Found: /favicon.ico
2018-01-01 17:33:30,740 [Thread-2981:139959578924800] [django.request:170] [base:get_response] [WARNING]- Not Found: /favicon.ico
2018-01-01 17:33:46,186 [Thread-3001:139959486899968] [django.request:170] [base:get_response] [WARNING]- Not Found: /favicon.ico
2018-01-01 17:34:05,163 [Thread-3021:139959486899968] [django.request:170] [base:get_response] [WARNING]- Not Found: /favicon.ico
2018-01-01 17:35:09,931 [Thread-3041:139959578924800] [django.request:170] [base:get_response] [WARNING]- Not Found: /favicon.ico
2018-01-01 17:35:21,723 [Thread-3061:139959495292672] [django.request:170] [base:get_response] [WARNING]- Not Found: /favicon.ico
2018-01-01 17:42:26,895 [Thread-3081:139959578924800] [django.request:170] [base:get_response] [WARNING]- Not Found: /favicon.ico
2018-01-01 17:46:55,192 [Thread-3100:139959478507264] [django.request:170] [base:get_response] [WARNING]- Not Found: /favicon.ico
2018-01-01 17:50:05,217 [Thread-3119:139959470114560] [django.request:170] [base:get_response] [WARNING]- Not Found: /favicon.ico
2018-01-01 17:50:10,990 [Thread-3138:139959461721856] [django.request:170] [base:get_response] [WARNING]- Not Found: /favicon.ico
2018-01-01 17:50:17,750 [Thread-3157:139959495292672] [django.request:170] [base:get_response] [WARNING]- Not Found: /favicon.ico
2018-01-01 17:50:28,192 [Thread-3176:139959495292672] [django.request:170] [base:get_response] [WARNING]- Not Found: /favicon.ico
2018-01-01 17:50:38,239 [Thread-3195:139959470114560] [django.request:170] [base:get_response] [WARNING]- Not Found: /favicon.ico
2018-01-01 17:50:44,203 [Thread-3214:139959478507264] [django.request:170] [base:get_response] [WARNING]- Not Found: /favicon.ico
2018-01-01 18:28:43,716 [Thread-3233:139959478507264] [django.request:170] [base:get_response] [WARNING]- Not Found: /favicon.ico
2018-01-01 18:30:04,998 [Thread-3252:139959470114560] [django.request:170] [base:get_response] [WARNING]- Not Found: /favicon.ico
2018-01-01 18:30:29,931 [Thread-3271:139959578924800] [django.request:170] [base:get_response] [WARNING]- Not Found: /favicon.ico
2018-01-01 18:41:52,628 [Thread-3290:139959461721856] [django.request:170] [base:get_response] [WARNING]- Not Found: /favicon.ico
2018-01-01 18:42:25,515 [Thread-3309:139959578924800] [django.request:170] [base:get_response] [WARNING]- Not Found: /favicon.ico
2018-01-01 18:42:56,019 [Thread-3328:139959486899968] [django.request:170] [base:get_response] [WARNING]- Not Found: /favicon.ico
2018-01-01 18:43:13,133 [Thread-3347:139959495292672] [django.request:170] [base:get_response] [WARNING]- Not Found: /favicon.ico
2018-01-01 18:43:22,603 [Thread-3366:139959478507264] [django.request:170] [base:get_response] [WARNING]- Not Found: /favicon.ico
2018-01-01 19:25:57,081 [Thread-3385:139959461721856] [django.request:170] [base:get_response] [WARNING]- Not Found: /favicon.ico
2018-01-01 19:26:41,828 [Thread-3406:139959470114560] [django.request:170] [base:get_response] [WARNING]- Not Found: /favicon.ico
2018-01-01 21:13:28,885 [Thread-2:140387626657536] [django.request:170] [base:get_response] [WARNING]- Not Found: /user/login/
2018-01-01 21:13:29,770 [Thread-7:140387615815424] [django.request:170] [base:get_response] [WARNING]- Not Found: /favicon.ico
2018-01-01 21:13:52,759 [Thread-48:140387607422720] [django.request:170] [base:get_response] [WARNING]- Not Found: /
2018-01-01 21:25:23,383 [Thread-4:139763087832832] [django.request:170] [base:get_response] [WARNING]- Not Found: /favicon.ico
2018-01-01 21:25:30,641 [Thread-5:139763087832832] [django.request:170] [base:get_response] [WARNING]- Not Found: /quantization/uploadimg/
2018-01-01 21:26:45,278 [Thread-2:140573433407232] [django.request:256] [base:handle_uncaught_exception] [ERROR]- Internal Server Error: /quantization/uploadimg/
Traceback (most recent call last):
  File "/root/.virtualenvs/student/lib/python3.5/site-packages/django/core/handlers/base.py", line 132, in get_response
    response = wrapped_callback(request, *callback_args, **callback_kwargs)
  File "/root/.virtualenvs/student/lib/python3.5/site-packages/django/views/decorators/csrf.py", line 58, in wrapped_view
    return view_func(*args, **kwargs)
  File "/root/student/quantization/views.py", line 63, in uploadimg
    return render(request, '/uploadimg.html')
  File "/root/.virtualenvs/student/lib/python3.5/site-packages/django/shortcuts.py", line 67, in render
    template_name, context, request=request, using=using)
  File "/root/.virtualenvs/student/lib/python3.5/site-packages/django/template/loader.py", line 98, in render_to_string
    template = get_template(template_name, using=using)
  File "/root/.virtualenvs/student/lib/python3.5/site-packages/django/template/loader.py", line 46, in get_template
    raise TemplateDoesNotExist(template_name)
django.template.base.TemplateDoesNotExist: /uploadimg.html
2018-01-01 21:53:17,342 [Thread-3:140098506532608] [django.request:256] [base:handle_uncaught_exception] [ERROR]- Internal Server Error: /quantization/uploadimg/
Traceback (most recent call last):
  File "/root/.virtualenvs/student/lib/python3.5/site-packages/django/db/backends/utils.py", line 64, in execute
    return self.cursor.execute(sql, params)
  File "/root/.virtualenvs/student/lib/python3.5/site-packages/django/db/backends/mysql/base.py", line 124, in execute
    return self.cursor.execute(query, args)
  File "/root/.virtualenvs/student/lib/python3.5/site-packages/pymysql/cursors.py", line 165, in execute
    result = self._query(query)
  File "/root/.virtualenvs/student/lib/python3.5/site-packages/pymysql/cursors.py", line 321, in _query
    conn.query(q)
  File "/root/.virtualenvs/student/lib/python3.5/site-packages/pymysql/connections.py", line 860, in query
    self._affected_rows = self._read_query_result(unbuffered=unbuffered)
  File "/root/.virtualenvs/student/lib/python3.5/site-packages/pymysql/connections.py", line 1061, in _read_query_result
    result.read()
  File "/root/.virtualenvs/student/lib/python3.5/site-packages/pymysql/connections.py", line 1349, in read
    first_packet = self.connection._read_packet()
  File "/root/.virtualenvs/student/lib/python3.5/site-packages/pymysql/connections.py", line 1018, in _read_packet
    packet.check_error()
  File "/root/.virtualenvs/student/lib/python3.5/site-packages/pymysql/connections.py", line 384, in check_error
    err.raise_mysql_exception(self._data)
  File "/root/.virtualenvs/student/lib/python3.5/site-packages/pymysql/err.py", line 107, in raise_mysql_exception
    raise errorclass(errno, errval)
pymysql.err.IntegrityError: (1048, "Column 'studentId_id' cannot be null")

The above exception was the direct cause of the following exception:

Traceback (most recent call last):
  File "/root/.virtualenvs/student/lib/python3.5/site-packages/django/core/handlers/base.py", line 132, in get_response
    response = wrapped_callback(request, *callback_args, **callback_kwargs)
  File "/root/.virtualenvs/student/lib/python3.5/site-packages/django/views/decorators/csrf.py", line 58, in wrapped_view
    return view_func(*args, **kwargs)
  File "/root/student/quantization/views.py", line 62, in uploadimg
    new_img.save()
  File "/root/.virtualenvs/student/lib/python3.5/site-packages/django/db/models/base.py", line 710, in save
    force_update=force_update, update_fields=update_fields)
  File "/root/.virtualenvs/student/lib/python3.5/site-packages/django/db/models/base.py", line 738, in save_base
    updated = self._save_table(raw, cls, force_insert, force_update, using, update_fields)
  File "/root/.virtualenvs/student/lib/python3.5/site-packages/django/db/models/base.py", line 822, in _save_table
    result = self._do_insert(cls._base_manager, using, fields, update_pk, raw)
  File "/root/.virtualenvs/student/lib/python3.5/site-packages/django/db/models/base.py", line 861, in _do_insert
    using=using, raw=raw)
  File "/root/.virtualenvs/student/lib/python3.5/site-packages/django/db/models/manager.py", line 127, in manager_method
    return getattr(self.get_queryset(), name)(*args, **kwargs)
  File "/root/.virtualenvs/student/lib/python3.5/site-packages/django/db/models/query.py", line 920, in _insert
    return query.get_compiler(using=using).execute_sql(return_id)
  File "/root/.virtualenvs/student/lib/python3.5/site-packages/django/db/models/sql/compiler.py", line 974, in execute_sql
    cursor.execute(sql, params)
  File "/root/.virtualenvs/student/lib/python3.5/site-packages/django/db/backends/utils.py", line 79, in execute
    return super(CursorDebugWrapper, self).execute(sql, params)
  File "/root/.virtualenvs/student/lib/python3.5/site-packages/django/db/backends/utils.py", line 64, in execute
    return self.cursor.execute(sql, params)
  File "/root/.virtualenvs/student/lib/python3.5/site-packages/django/db/utils.py", line 97, in __exit__
    six.reraise(dj_exc_type, dj_exc_value, traceback)
  File "/root/.virtualenvs/student/lib/python3.5/site-packages/django/utils/six.py", line 658, in reraise
    raise value.with_traceback(tb)
  File "/root/.virtualenvs/student/lib/python3.5/site-packages/django/db/backends/utils.py", line 64, in execute
    return self.cursor.execute(sql, params)
  File "/root/.virtualenvs/student/lib/python3.5/site-packages/django/db/backends/mysql/base.py", line 124, in execute
    return self.cursor.execute(query, args)
  File "/root/.virtualenvs/student/lib/python3.5/site-packages/pymysql/cursors.py", line 165, in execute
    result = self._query(query)
  File "/root/.virtualenvs/student/lib/python3.5/site-packages/pymysql/cursors.py", line 321, in _query
    conn.query(q)
  File "/root/.virtualenvs/student/lib/python3.5/site-packages/pymysql/connections.py", line 860, in query
    self._affected_rows = self._read_query_result(unbuffered=unbuffered)
  File "/root/.virtualenvs/student/lib/python3.5/site-packages/pymysql/connections.py", line 1061, in _read_query_result
    result.read()
  File "/root/.virtualenvs/student/lib/python3.5/site-packages/pymysql/connections.py", line 1349, in read
    first_packet = self.connection._read_packet()
  File "/root/.virtualenvs/student/lib/python3.5/site-packages/pymysql/connections.py", line 1018, in _read_packet
    packet.check_error()
  File "/root/.virtualenvs/student/lib/python3.5/site-packages/pymysql/connections.py", line 384, in check_error
    err.raise_mysql_exception(self._data)
  File "/root/.virtualenvs/student/lib/python3.5/site-packages/pymysql/err.py", line 107, in raise_mysql_exception
    raise errorclass(errno, errval)
django.db.utils.IntegrityError: (1048, "Column 'studentId_id' cannot be null")
2018-01-01 21:56:36,628 [Thread-2:139760281392896] [django.request:256] [base:handle_uncaught_exception] [ERROR]- Internal Server Error: /quantization/uploadimg/
Traceback (most recent call last):
  File "/root/.virtualenvs/student/lib/python3.5/site-packages/django/core/handlers/base.py", line 132, in get_response
    response = wrapped_callback(request, *callback_args, **callback_kwargs)
  File "/root/.virtualenvs/student/lib/python3.5/site-packages/django/views/decorators/csrf.py", line 58, in wrapped_view
    return view_func(*args, **kwargs)
  File "/root/student/quantization/views.py", line 61, in uploadimg
    studentId=0
  File "/root/.virtualenvs/student/lib/python3.5/site-packages/django/db/models/base.py", line 468, in __init__
    setattr(self, field.name, rel_obj)
  File "/root/.virtualenvs/student/lib/python3.5/site-packages/django/db/models/fields/related.py", line 635, in __set__
    self.field.rel.to._meta.object_name,
ValueError: Cannot assign "0": "StudentAnswer.studentId" must be a "StudentInfo" instance.
2018-01-01 21:57:01,622 [Thread-2:140088829183744] [django.request:256] [base:handle_uncaught_exception] [ERROR]- Internal Server Error: /quantization/uploadimg/
Traceback (most recent call last):
  File "/root/.virtualenvs/student/lib/python3.5/site-packages/django/core/handlers/base.py", line 132, in get_response
    response = wrapped_callback(request, *callback_args, **callback_kwargs)
  File "/root/.virtualenvs/student/lib/python3.5/site-packages/django/views/decorators/csrf.py", line 58, in wrapped_view
    return view_func(*args, **kwargs)
  File "/root/student/quantization/views.py", line 61, in uploadimg
    studentId="0"
  File "/root/.virtualenvs/student/lib/python3.5/site-packages/django/db/models/base.py", line 468, in __init__
    setattr(self, field.name, rel_obj)
  File "/root/.virtualenvs/student/lib/python3.5/site-packages/django/db/models/fields/related.py", line 635, in __set__
    self.field.rel.to._meta.object_name,
ValueError: Cannot assign "'0'": "StudentAnswer.studentId" must be a "StudentInfo" instance.
2018-01-01 21:57:07,515 [Thread-5:140088829183744] [django.request:256] [base:handle_uncaught_exception] [ERROR]- Internal Server Error: /quantization/uploadimg/
Traceback (most recent call last):
  File "/root/.virtualenvs/student/lib/python3.5/site-packages/django/core/handlers/base.py", line 132, in get_response
    response = wrapped_callback(request, *callback_args, **callback_kwargs)
  File "/root/.virtualenvs/student/lib/python3.5/site-packages/django/views/decorators/csrf.py", line 58, in wrapped_view
    return view_func(*args, **kwargs)
  File "/root/student/quantization/views.py", line 61, in uploadimg
    studentId="0"
  File "/root/.virtualenvs/student/lib/python3.5/site-packages/django/db/models/base.py", line 468, in __init__
    setattr(self, field.name, rel_obj)
  File "/root/.virtualenvs/student/lib/python3.5/site-packages/django/db/models/fields/related.py", line 635, in __set__
    self.field.rel.to._meta.object_name,
ValueError: Cannot assign "'0'": "StudentAnswer.studentId" must be a "StudentInfo" instance.
2018-01-01 21:57:17,476 [Thread-2:140480208217856] [django.request:256] [base:handle_uncaught_exception] [ERROR]- Internal Server Error: /quantization/uploadimg/
Traceback (most recent call last):
  File "/root/.virtualenvs/student/lib/python3.5/site-packages/django/core/handlers/base.py", line 132, in get_response
    response = wrapped_callback(request, *callback_args, **callback_kwargs)
  File "/root/.virtualenvs/student/lib/python3.5/site-packages/django/views/decorators/csrf.py", line 58, in wrapped_view
    return view_func(*args, **kwargs)
  File "/root/student/quantization/views.py", line 61, in uploadimg
    studentId="lala"
  File "/root/.virtualenvs/student/lib/python3.5/site-packages/django/db/models/base.py", line 468, in __init__
    setattr(self, field.name, rel_obj)
  File "/root/.virtualenvs/student/lib/python3.5/site-packages/django/db/models/fields/related.py", line 635, in __set__
    self.field.rel.to._meta.object_name,
ValueError: Cannot assign "'lala'": "StudentAnswer.studentId" must be a "StudentInfo" instance.
2018-01-01 22:00:18,858 [Thread-2:140044388005632] [django.request:256] [base:handle_uncaught_exception] [ERROR]- Internal Server Error: /quantization/uploadimg/
Traceback (most recent call last):
  File "/root/.virtualenvs/student/lib/python3.5/site-packages/django/core/handlers/base.py", line 132, in get_response
    response = wrapped_callback(request, *callback_args, **callback_kwargs)
  File "/root/.virtualenvs/student/lib/python3.5/site-packages/django/views/decorators/csrf.py", line 58, in wrapped_view
    return view_func(*args, **kwargs)
  File "/root/student/quantization/views.py", line 61, in uploadimg
    studentId="2016"
  File "/root/.virtualenvs/student/lib/python3.5/site-packages/django/db/models/base.py", line 468, in __init__
    setattr(self, field.name, rel_obj)
  File "/root/.virtualenvs/student/lib/python3.5/site-packages/django/db/models/fields/related.py", line 635, in __set__
    self.field.rel.to._meta.object_name,
ValueError: Cannot assign "'2016'": "StudentAnswer.studentId" must be a "StudentInfo" instance.
2018-01-01 22:16:23,378 [Thread-4:139804574856960] [django.request:256] [base:handle_uncaught_exception] [ERROR]- Internal Server Error: /quantization/uploadimg/
Traceback (most recent call last):
  File "/root/.virtualenvs/student/lib/python3.5/site-packages/django/core/handlers/base.py", line 132, in get_response
    response = wrapped_callback(request, *callback_args, **callback_kwargs)
  File "/root/.virtualenvs/student/lib/python3.5/site-packages/django/views/decorators/csrf.py", line 58, in wrapped_view
    return view_func(*args, **kwargs)
  File "/root/student/quantization/views.py", line 61, in uploadimg
    studentId=StudentInfo.objects.get(studentId="2016")
  File "/root/.virtualenvs/student/lib/python3.5/site-packages/django/db/models/manager.py", line 127, in manager_method
    return getattr(self.get_queryset(), name)(*args, **kwargs)
  File "/root/.virtualenvs/student/lib/python3.5/site-packages/django/db/models/query.py", line 334, in get
    self.model._meta.object_name
quantization.models.DoesNotExist: StudentInfo matching query does not exist.
2018-01-01 22:16:38,370 [Thread-2:139916603565824] [django.request:256] [base:handle_uncaught_exception] [ERROR]- Internal Server Error: /quantization/uploadimg/
Traceback (most recent call last):
  File "/root/.virtualenvs/student/lib/python3.5/site-packages/django/core/handlers/base.py", line 132, in get_response
    response = wrapped_callback(request, *callback_args, **callback_kwargs)
  File "/root/.virtualenvs/student/lib/python3.5/site-packages/django/views/decorators/csrf.py", line 58, in wrapped_view
    return view_func(*args, **kwargs)
  File "/root/student/quantization/views.py", line 61, in uploadimg
    studentId=StudentInfo.objects.get("2016")
  File "/root/.virtualenvs/student/lib/python3.5/site-packages/django/db/models/manager.py", line 127, in manager_method
    return getattr(self.get_queryset(), name)(*args, **kwargs)
  File "/root/.virtualenvs/student/lib/python3.5/site-packages/django/db/models/query.py", line 325, in get
    clone = self.filter(*args, **kwargs)
  File "/root/.virtualenvs/student/lib/python3.5/site-packages/django/db/models/query.py", line 679, in filter
    return self._filter_or_exclude(False, *args, **kwargs)
  File "/root/.virtualenvs/student/lib/python3.5/site-packages/django/db/models/query.py", line 697, in _filter_or_exclude
    clone.query.add_q(Q(*args, **kwargs))
  File "/root/.virtualenvs/student/lib/python3.5/site-packages/django/db/models/sql/query.py", line 1309, in add_q
    clause, require_inner = self._add_q(where_part, self.used_aliases)
  File "/root/.virtualenvs/student/lib/python3.5/site-packages/django/db/models/sql/query.py", line 1337, in _add_q
    allow_joins=allow_joins, split_subq=split_subq,
  File "/root/.virtualenvs/student/lib/python3.5/site-packages/django/db/models/sql/query.py", line 1146, in build_filter
    arg, value = filter_expr
ValueError: too many values to unpack (expected 2)
2018-01-01 22:19:30,817 [Thread-4:140693330720512] [django.request:256] [base:handle_uncaught_exception] [ERROR]- Internal Server Error: /quantization/uploadimg/
Traceback (most recent call last):
  File "/root/.virtualenvs/student/lib/python3.5/site-packages/django/db/models/options.py", line 552, in get_field
    return self.fields_map[field_name]
KeyError: 'studentid_id'

During handling of the above exception, another exception occurred:

Traceback (most recent call last):
  File "/root/.virtualenvs/student/lib/python3.5/site-packages/django/db/models/sql/query.py", line 1367, in names_to_path
    field = opts.get_field(name)
  File "/root/.virtualenvs/student/lib/python3.5/site-packages/django/db/models/options.py", line 554, in get_field
    raise FieldDoesNotExist('%s has no field named %r' % (self.object_name, field_name))
django.core.exceptions.FieldDoesNotExist: StudentInfo has no field named 'studentid_id'

During handling of the above exception, another exception occurred:

Traceback (most recent call last):
  File "/root/.virtualenvs/student/lib/python3.5/site-packages/django/core/handlers/base.py", line 132, in get_response
    response = wrapped_callback(request, *callback_args, **callback_kwargs)
  File "/root/.virtualenvs/student/lib/python3.5/site-packages/django/views/decorators/csrf.py", line 58, in wrapped_view
    return view_func(*args, **kwargs)
  File "/root/student/quantization/views.py", line 61, in uploadimg
    studentId=StudentInfo.objects.get(studentid_id="2016")
  File "/root/.virtualenvs/student/lib/python3.5/site-packages/django/db/models/manager.py", line 127, in manager_method
    return getattr(self.get_queryset(), name)(*args, **kwargs)
  File "/root/.virtualenvs/student/lib/python3.5/site-packages/django/db/models/query.py", line 325, in get
    clone = self.filter(*args, **kwargs)
  File "/root/.virtualenvs/student/lib/python3.5/site-packages/django/db/models/query.py", line 679, in filter
    return self._filter_or_exclude(False, *args, **kwargs)
  File "/root/.virtualenvs/student/lib/python3.5/site-packages/django/db/models/query.py", line 697, in _filter_or_exclude
    clone.query.add_q(Q(*args, **kwargs))
  File "/root/.virtualenvs/student/lib/python3.5/site-packages/django/db/models/sql/query.py", line 1309, in add_q
    clause, require_inner = self._add_q(where_part, self.used_aliases)
  File "/root/.virtualenvs/student/lib/python3.5/site-packages/django/db/models/sql/query.py", line 1337, in _add_q
    allow_joins=allow_joins, split_subq=split_subq,
  File "/root/.virtualenvs/student/lib/python3.5/site-packages/django/db/models/sql/query.py", line 1149, in build_filter
    lookups, parts, reffed_expression = self.solve_lookup_type(arg)
  File "/root/.virtualenvs/student/lib/python3.5/site-packages/django/db/models/sql/query.py", line 1035, in solve_lookup_type
    _, field, _, lookup_parts = self.names_to_path(lookup_splitted, self.get_meta())
  File "/root/.virtualenvs/student/lib/python3.5/site-packages/django/db/models/sql/query.py", line 1396, in names_to_path
    "Choices are: %s" % (name, ", ".join(available)))
django.core.exceptions.FieldError: Cannot resolve keyword 'studentid_id' into field. Choices are: StudentAnswer, clazz, department, gender, major, name, nation, sfz, studentId
2018-01-01 22:34:34,064 [Thread-12:140693330720512] [django.request:256] [base:handle_uncaught_exception] [ERROR]- Internal Server Error: /admin/quantization/studentanswer/add/
Traceback (most recent call last):
  File "/root/.virtualenvs/student/lib/python3.5/site-packages/django/core/handlers/base.py", line 132, in get_response
    response = wrapped_callback(request, *callback_args, **callback_kwargs)
  File "/root/.virtualenvs/student/lib/python3.5/site-packages/django/contrib/admin/options.py", line 616, in wrapper
    return self.admin_site.admin_view(view)(*args, **kwargs)
  File "/root/.virtualenvs/student/lib/python3.5/site-packages/django/utils/decorators.py", line 110, in _wrapped_view
    response = view_func(request, *args, **kwargs)
  File "/root/.virtualenvs/student/lib/python3.5/site-packages/django/views/decorators/cache.py", line 57, in _wrapped_view_func
    response = view_func(request, *args, **kwargs)
  File "/root/.virtualenvs/student/lib/python3.5/site-packages/django/contrib/admin/sites.py", line 233, in inner
    return view(request, *args, **kwargs)
  File "/root/.virtualenvs/student/lib/python3.5/site-packages/django/contrib/admin/options.py", line 1516, in add_view
    return self.changeform_view(request, None, form_url, extra_context)
  File "/root/.virtualenvs/student/lib/python3.5/site-packages/django/utils/decorators.py", line 34, in _wrapper
    return bound_func(*args, **kwargs)
  File "/root/.virtualenvs/student/lib/python3.5/site-packages/django/utils/decorators.py", line 110, in _wrapped_view
    response = view_func(request, *args, **kwargs)
  File "/root/.virtualenvs/student/lib/python3.5/site-packages/django/utils/decorators.py", line 30, in bound_func
    return func.__get__(self, type(self))(*args2, **kwargs2)
  File "/usr/lib/python3.5/contextlib.py", line 30, in inner
    return func(*args, **kwds)
  File "/root/.virtualenvs/student/lib/python3.5/site-packages/django/contrib/admin/options.py", line 1470, in changeform_view
    self.log_addition(request, new_object)
  File "/root/.virtualenvs/student/lib/python3.5/site-packages/django/contrib/admin/options.py", line 810, in log_addition
    object_repr=force_text(object),
  File "/root/.virtualenvs/student/lib/python3.5/site-packages/django/utils/encoding.py", line 90, in force_text
    s = six.text_type(s)
TypeError: __str__ returned non-string (type StudentInfo)
2018-01-01 22:35:05,437 [Thread-30:140693284992768] [django.request:256] [base:handle_uncaught_exception] [ERROR]- Internal Server Error: /admin/quantization/studentanswer/add/
Traceback (most recent call last):
  File "/root/.virtualenvs/student/lib/python3.5/site-packages/django/core/handlers/base.py", line 132, in get_response
    response = wrapped_callback(request, *callback_args, **callback_kwargs)
  File "/root/.virtualenvs/student/lib/python3.5/site-packages/django/contrib/admin/options.py", line 616, in wrapper
    return self.admin_site.admin_view(view)(*args, **kwargs)
  File "/root/.virtualenvs/student/lib/python3.5/site-packages/django/utils/decorators.py", line 110, in _wrapped_view
    response = view_func(request, *args, **kwargs)
  File "/root/.virtualenvs/student/lib/python3.5/site-packages/django/views/decorators/cache.py", line 57, in _wrapped_view_func
    response = view_func(request, *args, **kwargs)
  File "/root/.virtualenvs/student/lib/python3.5/site-packages/django/contrib/admin/sites.py", line 233, in inner
    return view(request, *args, **kwargs)
  File "/root/.virtualenvs/student/lib/python3.5/site-packages/django/contrib/admin/options.py", line 1516, in add_view
    return self.changeform_view(request, None, form_url, extra_context)
  File "/root/.virtualenvs/student/lib/python3.5/site-packages/django/utils/decorators.py", line 34, in _wrapper
    return bound_func(*args, **kwargs)
  File "/root/.virtualenvs/student/lib/python3.5/site-packages/django/utils/decorators.py", line 110, in _wrapped_view
    response = view_func(request, *args, **kwargs)
  File "/root/.virtualenvs/student/lib/python3.5/site-packages/django/utils/decorators.py", line 30, in bound_func
    return func.__get__(self, type(self))(*args2, **kwargs2)
  File "/usr/lib/python3.5/contextlib.py", line 30, in inner
    return func(*args, **kwds)
  File "/root/.virtualenvs/student/lib/python3.5/site-packages/django/contrib/admin/options.py", line 1470, in changeform_view
    self.log_addition(request, new_object)
  File "/root/.virtualenvs/student/lib/python3.5/site-packages/django/contrib/admin/options.py", line 810, in log_addition
    object_repr=force_text(object),
  File "/root/.virtualenvs/student/lib/python3.5/site-packages/django/utils/encoding.py", line 90, in force_text
    s = six.text_type(s)
TypeError: __str__ returned non-string (type StudentInfo)
2018-01-01 22:35:38,275 [Thread-21:139947536164608] [django.request:170] [base:get_response] [WARNING]- Not Found: /media/studentDatum/1_4tj9JQj.png
2018-01-01 22:40:48,478 [Thread-38:140466128983808] [django.request:256] [base:handle_uncaught_exception] [ERROR]- Internal Server Error: /quantization/uploadimg/
Traceback (most recent call last):
  File "/root/.virtualenvs/student/lib/python3.5/site-packages/django/db/models/options.py", line 552, in get_field
    return self.fields_map[field_name]
KeyError: 'studentid_id'

During handling of the above exception, another exception occurred:

Traceback (most recent call last):
  File "/root/.virtualenvs/student/lib/python3.5/site-packages/django/db/models/sql/query.py", line 1367, in names_to_path
    field = opts.get_field(name)
  File "/root/.virtualenvs/student/lib/python3.5/site-packages/django/db/models/options.py", line 554, in get_field
    raise FieldDoesNotExist('%s has no field named %r' % (self.object_name, field_name))
django.core.exceptions.FieldDoesNotExist: StudentInfo has no field named 'studentid_id'

During handling of the above exception, another exception occurred:

Traceback (most recent call last):
  File "/root/.virtualenvs/student/lib/python3.5/site-packages/django/core/handlers/base.py", line 132, in get_response
    response = wrapped_callback(request, *callback_args, **callback_kwargs)
  File "/root/.virtualenvs/student/lib/python3.5/site-packages/django/views/decorators/csrf.py", line 58, in wrapped_view
    return view_func(*args, **kwargs)
  File "/root/student/quantization/views.py", line 61, in uploadimg
    studentId=StudentInfo.objects.get(studentid_id="2016010978")
  File "/root/.virtualenvs/student/lib/python3.5/site-packages/django/db/models/manager.py", line 127, in manager_method
    return getattr(self.get_queryset(), name)(*args, **kwargs)
  File "/root/.virtualenvs/student/lib/python3.5/site-packages/django/db/models/query.py", line 325, in get
    clone = self.filter(*args, **kwargs)
  File "/root/.virtualenvs/student/lib/python3.5/site-packages/django/db/models/query.py", line 679, in filter
    return self._filter_or_exclude(False, *args, **kwargs)
  File "/root/.virtualenvs/student/lib/python3.5/site-packages/django/db/models/query.py", line 697, in _filter_or_exclude
    clone.query.add_q(Q(*args, **kwargs))
  File "/root/.virtualenvs/student/lib/python3.5/site-packages/django/db/models/sql/query.py", line 1309, in add_q
    clause, require_inner = self._add_q(where_part, self.used_aliases)
  File "/root/.virtualenvs/student/lib/python3.5/site-packages/django/db/models/sql/query.py", line 1337, in _add_q
    allow_joins=allow_joins, split_subq=split_subq,
  File "/root/.virtualenvs/student/lib/python3.5/site-packages/django/db/models/sql/query.py", line 1149, in build_filter
    lookups, parts, reffed_expression = self.solve_lookup_type(arg)
  File "/root/.virtualenvs/student/lib/python3.5/site-packages/django/db/models/sql/query.py", line 1035, in solve_lookup_type
    _, field, _, lookup_parts = self.names_to_path(lookup_splitted, self.get_meta())
  File "/root/.virtualenvs/student/lib/python3.5/site-packages/django/db/models/sql/query.py", line 1396, in names_to_path
    "Choices are: %s" % (name, ", ".join(available)))
django.core.exceptions.FieldError: Cannot resolve keyword 'studentid_id' into field. Choices are: StudentAnswer, clazz, department, gender, major, name, nation, sfz, studentId
2018-01-01 22:41:14,721 [Thread-4:140041032562432] [django.request:256] [base:handle_uncaught_exception] [ERROR]- Internal Server Error: /quantization/uploadimg/
Traceback (most recent call last):
  File "/root/.virtualenvs/student/lib/python3.5/site-packages/django/db/models/options.py", line 552, in get_field
    return self.fields_map[field_name]
KeyError: 'studentid'

During handling of the above exception, another exception occurred:

Traceback (most recent call last):
  File "/root/.virtualenvs/student/lib/python3.5/site-packages/django/db/models/sql/query.py", line 1367, in names_to_path
    field = opts.get_field(name)
  File "/root/.virtualenvs/student/lib/python3.5/site-packages/django/db/models/options.py", line 554, in get_field
    raise FieldDoesNotExist('%s has no field named %r' % (self.object_name, field_name))
django.core.exceptions.FieldDoesNotExist: StudentInfo has no field named 'studentid'

During handling of the above exception, another exception occurred:

Traceback (most recent call last):
  File "/root/.virtualenvs/student/lib/python3.5/site-packages/django/core/handlers/base.py", line 132, in get_response
    response = wrapped_callback(request, *callback_args, **callback_kwargs)
  File "/root/.virtualenvs/student/lib/python3.5/site-packages/django/views/decorators/csrf.py", line 58, in wrapped_view
    return view_func(*args, **kwargs)
  File "/root/student/quantization/views.py", line 61, in uploadimg
    studentId=StudentInfo.objects.get(studentid="2016010978")
  File "/root/.virtualenvs/student/lib/python3.5/site-packages/django/db/models/manager.py", line 127, in manager_method
    return getattr(self.get_queryset(), name)(*args, **kwargs)
  File "/root/.virtualenvs/student/lib/python3.5/site-packages/django/db/models/query.py", line 325, in get
    clone = self.filter(*args, **kwargs)
  File "/root/.virtualenvs/student/lib/python3.5/site-packages/django/db/models/query.py", line 679, in filter
    return self._filter_or_exclude(False, *args, **kwargs)
  File "/root/.virtualenvs/student/lib/python3.5/site-packages/django/db/models/query.py", line 697, in _filter_or_exclude
    clone.query.add_q(Q(*args, **kwargs))
  File "/root/.virtualenvs/student/lib/python3.5/site-packages/django/db/models/sql/query.py", line 1309, in add_q
    clause, require_inner = self._add_q(where_part, self.used_aliases)
  File "/root/.virtualenvs/student/lib/python3.5/site-packages/django/db/models/sql/query.py", line 1337, in _add_q
    allow_joins=allow_joins, split_subq=split_subq,
  File "/root/.virtualenvs/student/lib/python3.5/site-packages/django/db/models/sql/query.py", line 1149, in build_filter
    lookups, parts, reffed_expression = self.solve_lookup_type(arg)
  File "/root/.virtualenvs/student/lib/python3.5/site-packages/django/db/models/sql/query.py", line 1035, in solve_lookup_type
    _, field, _, lookup_parts = self.names_to_path(lookup_splitted, self.get_meta())
  File "/root/.virtualenvs/student/lib/python3.5/site-packages/django/db/models/sql/query.py", line 1396, in names_to_path
    "Choices are: %s" % (name, ", ".join(available)))
django.core.exceptions.FieldError: Cannot resolve keyword 'studentid' into field. Choices are: StudentAnswer, clazz, department, gender, major, name, nation, sfz, studentId
2018-01-01 22:42:47,996 [Thread-2:140156082050816] [django.request:256] [base:handle_uncaught_exception] [ERROR]- Internal Server Error: /admin/quantization/studentanswer/4/
Traceback (most recent call last):
  File "/root/.virtualenvs/student/lib/python3.5/site-packages/django/core/handlers/base.py", line 164, in get_response
    response = response.render()
  File "/root/.virtualenvs/student/lib/python3.5/site-packages/django/template/response.py", line 158, in render
    self.content = self.rendered_content
  File "/root/.virtualenvs/student/lib/python3.5/site-packages/django/template/response.py", line 135, in rendered_content
    content = template.render(context, self._request)
  File "/root/.virtualenvs/student/lib/python3.5/site-packages/django/template/backends/django.py", line 74, in render
    return self.template.render(context)
  File "/root/.virtualenvs/student/lib/python3.5/site-packages/django/template/base.py", line 209, in render
    return self._render(context)
  File "/root/.virtualenvs/student/lib/python3.5/site-packages/django/template/base.py", line 201, in _render
    return self.nodelist.render(context)
  File "/root/.virtualenvs/student/lib/python3.5/site-packages/django/template/base.py", line 903, in render
    bit = self.render_node(node, context)
  File "/root/.virtualenvs/student/lib/python3.5/site-packages/django/template/debug.py", line 79, in render_node
    return node.render(context)
  File "/root/.virtualenvs/student/lib/python3.5/site-packages/django/template/loader_tags.py", line 135, in render
    return compiled_parent._render(context)
  File "/root/.virtualenvs/student/lib/python3.5/site-packages/django/template/base.py", line 201, in _render
    return self.nodelist.render(context)
  File "/root/.virtualenvs/student/lib/python3.5/site-packages/django/template/base.py", line 903, in render
    bit = self.render_node(node, context)
  File "/root/.virtualenvs/student/lib/python3.5/site-packages/django/template/debug.py", line 79, in render_node
    return node.render(context)
  File "/root/.virtualenvs/student/lib/python3.5/site-packages/django/template/loader_tags.py", line 135, in render
    return compiled_parent._render(context)
  File "/root/.virtualenvs/student/lib/python3.5/site-packages/django/template/base.py", line 201, in _render
    return self.nodelist.render(context)
  File "/root/.virtualenvs/student/lib/python3.5/site-packages/django/template/base.py", line 903, in render
    bit = self.render_node(node, context)
  File "/root/.virtualenvs/student/lib/python3.5/site-packages/django/template/debug.py", line 79, in render_node
    return node.render(context)
  File "/root/.virtualenvs/student/lib/python3.5/site-packages/django/template/defaulttags.py", line 329, in render
    return nodelist.render(context)
  File "/root/.virtualenvs/student/lib/python3.5/site-packages/django/template/base.py", line 903, in render
    bit = self.render_node(node, context)
  File "/root/.virtualenvs/student/lib/python3.5/site-packages/django/template/debug.py", line 79, in render_node
    return node.render(context)
  File "/root/.virtualenvs/student/lib/python3.5/site-packages/django/template/loader_tags.py", line 65, in render
    result = block.nodelist.render(context)
  File "/root/.virtualenvs/student/lib/python3.5/site-packages/django/template/base.py", line 903, in render
    bit = self.render_node(node, context)
  File "/root/.virtualenvs/student/lib/python3.5/site-packages/django/template/debug.py", line 79, in render_node
    return node.render(context)
  File "/root/.virtualenvs/student/lib/python3.5/site-packages/django/template/defaulttags.py", line 329, in render
    return nodelist.render(context)
  File "/root/.virtualenvs/student/lib/python3.5/site-packages/django/template/base.py", line 903, in render
    bit = self.render_node(node, context)
  File "/root/.virtualenvs/student/lib/python3.5/site-packages/django/template/debug.py", line 79, in render_node
    return node.render(context)
  File "/root/.virtualenvs/student/lib/python3.5/site-packages/django/template/debug.py", line 89, in render
    output = self.filter_expression.resolve(context)
  File "/root/.virtualenvs/student/lib/python3.5/site-packages/django/template/base.py", line 674, in resolve
    new_obj = func(obj, *arg_vals)
  File "/root/.virtualenvs/student/lib/python3.5/site-packages/django/template/defaultfilters.py", line 45, in _dec
    args[0] = force_text(args[0])
  File "/root/.virtualenvs/student/lib/python3.5/site-packages/django/utils/encoding.py", line 90, in force_text
    s = six.text_type(s)
TypeError: __str__ returned non-string (type StudentInfo)
2018-01-01 22:43:04,295 [Thread-30:140155847436032] [django.request:256] [base:handle_uncaught_exception] [ERROR]- Internal Server Error: /admin/quantization/studentanswer/4/
Traceback (most recent call last):
  File "/root/.virtualenvs/student/lib/python3.5/site-packages/django/core/handlers/base.py", line 164, in get_response
    response = response.render()
  File "/root/.virtualenvs/student/lib/python3.5/site-packages/django/template/response.py", line 158, in render
    self.content = self.rendered_content
  File "/root/.virtualenvs/student/lib/python3.5/site-packages/django/template/response.py", line 135, in rendered_content
    content = template.render(context, self._request)
  File "/root/.virtualenvs/student/lib/python3.5/site-packages/django/template/backends/django.py", line 74, in render
    return self.template.render(context)
  File "/root/.virtualenvs/student/lib/python3.5/site-packages/django/template/base.py", line 209, in render
    return self._render(context)
  File "/root/.virtualenvs/student/lib/python3.5/site-packages/django/template/base.py", line 201, in _render
    return self.nodelist.render(context)
  File "/root/.virtualenvs/student/lib/python3.5/site-packages/django/template/base.py", line 903, in render
    bit = self.render_node(node, context)
  File "/root/.virtualenvs/student/lib/python3.5/site-packages/django/template/debug.py", line 79, in render_node
    return node.render(context)
  File "/root/.virtualenvs/student/lib/python3.5/site-packages/django/template/loader_tags.py", line 135, in render
    return compiled_parent._render(context)
  File "/root/.virtualenvs/student/lib/python3.5/site-packages/django/template/base.py", line 201, in _render
    return self.nodelist.render(context)
  File "/root/.virtualenvs/student/lib/python3.5/site-packages/django/template/base.py", line 903, in render
    bit = self.render_node(node, context)
  File "/root/.virtualenvs/student/lib/python3.5/site-packages/django/template/debug.py", line 79, in render_node
    return node.render(context)
  File "/root/.virtualenvs/student/lib/python3.5/site-packages/django/template/loader_tags.py", line 135, in render
    return compiled_parent._render(context)
  File "/root/.virtualenvs/student/lib/python3.5/site-packages/django/template/base.py", line 201, in _render
    return self.nodelist.render(context)
  File "/root/.virtualenvs/student/lib/python3.5/site-packages/django/template/base.py", line 903, in render
    bit = self.render_node(node, context)
  File "/root/.virtualenvs/student/lib/python3.5/site-packages/django/template/debug.py", line 79, in render_node
    return node.render(context)
  File "/root/.virtualenvs/student/lib/python3.5/site-packages/django/template/defaulttags.py", line 329, in render
    return nodelist.render(context)
  File "/root/.virtualenvs/student/lib/python3.5/site-packages/django/template/base.py", line 903, in render
    bit = self.render_node(node, context)
  File "/root/.virtualenvs/student/lib/python3.5/site-packages/django/template/debug.py", line 79, in render_node
    return node.render(context)
  File "/root/.virtualenvs/student/lib/python3.5/site-packages/django/template/loader_tags.py", line 65, in render
    result = block.nodelist.render(context)
  File "/root/.virtualenvs/student/lib/python3.5/site-packages/django/template/base.py", line 903, in render
    bit = self.render_node(node, context)
  File "/root/.virtualenvs/student/lib/python3.5/site-packages/django/template/debug.py", line 79, in render_node
    return node.render(context)
  File "/root/.virtualenvs/student/lib/python3.5/site-packages/django/template/defaulttags.py", line 329, in render
    return nodelist.render(context)
  File "/root/.virtualenvs/student/lib/python3.5/site-packages/django/template/base.py", line 903, in render
    bit = self.render_node(node, context)
  File "/root/.virtualenvs/student/lib/python3.5/site-packages/django/template/debug.py", line 79, in render_node
    return node.render(context)
  File "/root/.virtualenvs/student/lib/python3.5/site-packages/django/template/debug.py", line 89, in render
    output = self.filter_expression.resolve(context)
  File "/root/.virtualenvs/student/lib/python3.5/site-packages/django/template/base.py", line 674, in resolve
    new_obj = func(obj, *arg_vals)
  File "/root/.virtualenvs/student/lib/python3.5/site-packages/django/template/defaultfilters.py", line 45, in _dec
    args[0] = force_text(args[0])
  File "/root/.virtualenvs/student/lib/python3.5/site-packages/django/utils/encoding.py", line 90, in force_text
    s = six.text_type(s)
TypeError: __str__ returned non-string (type StudentInfo)
2018-01-01 22:43:25,090 [Thread-14:140635858695936] [django.request:256] [base:handle_uncaught_exception] [ERROR]- Internal Server Error: /admin/quantization/studentanswer/4/
Traceback (most recent call last):
  File "/root/.virtualenvs/student/lib/python3.5/site-packages/django/core/handlers/base.py", line 164, in get_response
    response = response.render()
  File "/root/.virtualenvs/student/lib/python3.5/site-packages/django/template/response.py", line 158, in render
    self.content = self.rendered_content
  File "/root/.virtualenvs/student/lib/python3.5/site-packages/django/template/response.py", line 135, in rendered_content
    content = template.render(context, self._request)
  File "/root/.virtualenvs/student/lib/python3.5/site-packages/django/template/backends/django.py", line 74, in render
    return self.template.render(context)
  File "/root/.virtualenvs/student/lib/python3.5/site-packages/django/template/base.py", line 209, in render
    return self._render(context)
  File "/root/.virtualenvs/student/lib/python3.5/site-packages/django/template/base.py", line 201, in _render
    return self.nodelist.render(context)
  File "/root/.virtualenvs/student/lib/python3.5/site-packages/django/template/base.py", line 903, in render
    bit = self.render_node(node, context)
  File "/root/.virtualenvs/student/lib/python3.5/site-packages/django/template/debug.py", line 79, in render_node
    return node.render(context)
  File "/root/.virtualenvs/student/lib/python3.5/site-packages/django/template/loader_tags.py", line 135, in render
    return compiled_parent._render(context)
  File "/root/.virtualenvs/student/lib/python3.5/site-packages/django/template/base.py", line 201, in _render
    return self.nodelist.render(context)
  File "/root/.virtualenvs/student/lib/python3.5/site-packages/django/template/base.py", line 903, in render
    bit = self.render_node(node, context)
  File "/root/.virtualenvs/student/lib/python3.5/site-packages/django/template/debug.py", line 79, in render_node
    return node.render(context)
  File "/root/.virtualenvs/student/lib/python3.5/site-packages/django/template/loader_tags.py", line 135, in render
    return compiled_parent._render(context)
  File "/root/.virtualenvs/student/lib/python3.5/site-packages/django/template/base.py", line 201, in _render
    return self.nodelist.render(context)
  File "/root/.virtualenvs/student/lib/python3.5/site-packages/django/template/base.py", line 903, in render
    bit = self.render_node(node, context)
  File "/root/.virtualenvs/student/lib/python3.5/site-packages/django/template/debug.py", line 79, in render_node
    return node.render(context)
  File "/root/.virtualenvs/student/lib/python3.5/site-packages/django/template/defaulttags.py", line 329, in render
    return nodelist.render(context)
  File "/root/.virtualenvs/student/lib/python3.5/site-packages/django/template/base.py", line 903, in render
    bit = self.render_node(node, context)
  File "/root/.virtualenvs/student/lib/python3.5/site-packages/django/template/debug.py", line 79, in render_node
    return node.render(context)
  File "/root/.virtualenvs/student/lib/python3.5/site-packages/django/template/loader_tags.py", line 65, in render
    result = block.nodelist.render(context)
  File "/root/.virtualenvs/student/lib/python3.5/site-packages/django/template/base.py", line 903, in render
    bit = self.render_node(node, context)
  File "/root/.virtualenvs/student/lib/python3.5/site-packages/django/template/debug.py", line 79, in render_node
    return node.render(context)
  File "/root/.virtualenvs/student/lib/python3.5/site-packages/django/template/defaulttags.py", line 329, in render
    return nodelist.render(context)
  File "/root/.virtualenvs/student/lib/python3.5/site-packages/django/template/base.py", line 903, in render
    bit = self.render_node(node, context)
  File "/root/.virtualenvs/student/lib/python3.5/site-packages/django/template/debug.py", line 79, in render_node
    return node.render(context)
  File "/root/.virtualenvs/student/lib/python3.5/site-packages/django/template/debug.py", line 89, in render
    output = self.filter_expression.resolve(context)
  File "/root/.virtualenvs/student/lib/python3.5/site-packages/django/template/base.py", line 674, in resolve
    new_obj = func(obj, *arg_vals)
  File "/root/.virtualenvs/student/lib/python3.5/site-packages/django/template/defaultfilters.py", line 45, in _dec
    args[0] = force_text(args[0])
  File "/root/.virtualenvs/student/lib/python3.5/site-packages/django/utils/encoding.py", line 90, in force_text
    s = six.text_type(s)
TypeError: __str__ returned non-string (type int)
2018-01-01 22:44:03,717 [Thread-25:139718521259776] [django.request:170] [base:get_response] [WARNING]- Not Found: /media/studentDatum/1.png
2018-01-01 22:45:40,237 [Thread-19:139634098050816] [django.request:170] [base:get_response] [WARNING]- Not Found: /media/studentDatum/1.png
2018-01-03 16:22:32,674 [Thread-2:140027759810304] [django.request:170] [base:get_response] [WARNING]- Not Found: /user/login_handle/
2018-01-03 17:24:16,103 [Thread-465:140027661113088] [django.request:170] [base:get_response] [WARNING]- Not Found: /favicon.ico
2018-01-03 17:25:04,241 [Thread-528:140027677898496] [django.request:170] [base:get_response] [WARNING]- Not Found: /favicon.ico
2018-01-03 17:25:09,209 [Thread-535:140027644327680] [django.request:170] [base:get_response] [WARNING]- Not Found: /favicon.ico
2018-01-04 09:30:50,933 [Thread-9:140369326937856] [django.request:170] [base:get_response] [WARNING]- Not Found: /favicon.ico
2018-01-05 10:04:21,521 [Thread-2794:140369310152448] [django.request:170] [base:get_response] [WARNING]- Not Found: /favicon.ico
2018-01-05 10:04:43,801 [Thread-2795:140369310152448] [django.request:170] [base:get_response] [WARNING]- Not Found: /user/login/
2018-01-05 14:56:26,183 [Thread-336:139715171575552] [django.request:170] [base:get_response] [WARNING]- Not Found: /user/login/
2018-01-06 10:30:05,041 [Thread-39:140184712640256] [django.request:170] [base:get_response] [WARNING]- Not Found: /
2018-01-06 19:05:51,946 [Thread-2:140554665031424] [django.request:170] [base:get_response] [WARNING]- Not Found: /user/login/
2018-01-07 09:58:11,483 [Thread-38:139795371349760] [django.request:170] [base:get_response] [WARNING]- Not Found: /user/login/
2018-01-07 13:37:13,292 [Thread-4:139735300712192] [django.request:170] [base:get_response] [WARNING]- Not Found: /favicon.ico
2018-01-07 13:47:59,119 [Thread-54:139716217267968] [django.request:170] [base:get_response] [WARNING]- Not Found: /user/login/
2018-01-07 15:50:10,034 [Thread-20:140279032641280] [django.request:170] [base:get_response] [WARNING]- Not Found: /favicon.ico
2018-01-07 15:50:43,294 [Thread-29:140279024248576] [django.request:170] [base:get_response] [WARNING]- Not Found: /favicon.ico
2018-01-07 15:52:38,029 [Thread-43:140279049426688] [django.request:170] [base:get_response] [WARNING]- Not Found: /favicon.ico
2018-01-07 16:28:28,415 [Thread-145:140279049426688] [django.request:170] [base:get_response] [WARNING]- Not Found: /favicon.ico
2018-01-07 16:29:23,005 [Thread-150:140279049426688] [django.request:170] [base:get_response] [WARNING]- Not Found: /favicon.ico
2018-01-07 16:29:24,202 [Thread-154:140279041033984] [django.request:170] [base:get_response] [WARNING]- Not Found: /favicon.ico
2018-01-07 16:30:15,073 [Thread-160:140279032641280] [django.request:170] [base:get_response] [WARNING]- Not Found: /favicon.ico
2018-01-07 17:13:42,858 [Thread-2:140130932504320] [django.request:256] [base:handle_uncaught_exception] [ERROR]- Internal Server Error: /democratic/save_signature/
Traceback (most recent call last):
  File "/root/.virtualenvs/student/lib/python3.5/site-packages/django/core/handlers/base.py", line 151, in get_response
    % (callback.__module__, view_name))
ValueError: The view democratic.views.save_signature didn't return an HttpResponse object. It returned None instead.
2018-01-07 17:13:57,422 [Thread-2:140348592486144] [django.request:256] [base:handle_uncaught_exception] [ERROR]- Internal Server Error: /democratic/save_signature/
Traceback (most recent call last):
  File "/root/.virtualenvs/student/lib/python3.5/site-packages/django/core/handlers/base.py", line 151, in get_response
    % (callback.__module__, view_name))
ValueError: The view democratic.views.save_signature didn't return an HttpResponse object. It returned None instead.
2018-01-07 17:14:13,374 [Thread-2:140307972847360] [django.request:256] [base:handle_uncaught_exception] [ERROR]- Internal Server Error: /democratic/save_signature/
Traceback (most recent call last):
  File "/root/.virtualenvs/student/lib/python3.5/site-packages/django/core/handlers/base.py", line 151, in get_response
    % (callback.__module__, view_name))
ValueError: The view democratic.views.save_signature didn't return an HttpResponse object. It returned None instead.
2018-01-07 17:38:48,191 [Thread-7:139621232121600] [django.request:98] [csrf:_reject] [WARNING]- Forbidden (CSRF token missing or incorrect.): /democratic/save_signature/
2018-01-08 09:21:21,676 [Thread-7:140307417257728] [django.request:170] [base:get_response] [WARNING]- Not Found: /user/login/
2018-01-08 09:23:22,433 [Thread-25:140307177924352] [django.request:170] [base:get_response] [WARNING]- Not Found: /user/login/
2018-01-08 09:23:22,513 [Thread-26:140307177924352] [django.request:170] [base:get_response] [WARNING]- Not Found: /favicon.ico
2018-01-08 09:32:37,900 [Thread-8:140452055054080] [django.request:170] [base:get_response] [WARNING]- Not Found: /democratic/index/
2018-01-08 14:23:06,258 [Thread-22:139633237141248] [django.request:170] [base:get_response] [WARNING]- Not Found: /user/login/
2018-01-08 14:23:47,339 [Thread-29:139633253926656] [django.request:170] [base:get_response] [WARNING]- Not Found: /user/login/
2018-01-08 14:31:26,399 [Thread-5:139647323551488] [django.request:256] [base:handle_uncaught_exception] [ERROR]- Internal Server Error: /democratic/save_signature/
Traceback (most recent call last):
  File "/root/.virtualenvs/student/lib/python3.5/site-packages/django/core/handlers/base.py", line 132, in get_response
    response = wrapped_callback(request, *callback_args, **callback_kwargs)
  File "/root/.virtualenvs/student/lib/python3.5/site-packages/django/views/decorators/csrf.py", line 58, in wrapped_view
    return view_func(*args, **kwargs)
  File "/root/student/democratic/views.py", line 30, in save_signature
    with open(filepath, "wb+") as f:
FileNotFoundError: [Errno 2] No such file or directory: '/signatureImage/default.jpg'
2018-01-08 14:31:36,755 [Thread-9:139647323551488] [django.request:256] [base:handle_uncaught_exception] [ERROR]- Internal Server Error: /democratic/save_signature/
Traceback (most recent call last):
  File "/root/.virtualenvs/student/lib/python3.5/site-packages/django/core/handlers/base.py", line 132, in get_response
    response = wrapped_callback(request, *callback_args, **callback_kwargs)
  File "/root/.virtualenvs/student/lib/python3.5/site-packages/django/views/decorators/csrf.py", line 58, in wrapped_view
    return view_func(*args, **kwargs)
  File "/root/student/democratic/views.py", line 30, in save_signature
    with open(filepath, "wb+") as f:
FileNotFoundError: [Errno 2] No such file or directory: '/signatureImage/default.jpg'
2018-01-08 14:33:14,718 [Thread-5:139648028780288] [django.request:256] [base:handle_uncaught_exception] [ERROR]- Internal Server Error: /democratic/save_signature/
Traceback (most recent call last):
  File "/root/.virtualenvs/student/lib/python3.5/site-packages/django/core/handlers/base.py", line 132, in get_response
    response = wrapped_callback(request, *callback_args, **callback_kwargs)
  File "/root/.virtualenvs/student/lib/python3.5/site-packages/django/views/decorators/csrf.py", line 58, in wrapped_view
    return view_func(*args, **kwargs)
  File "/root/student/democratic/views.py", line 30, in save_signature
    with open(filepath, "wb+") as f:
FileNotFoundError: [Errno 2] No such file or directory: '/root/student/media/signatureImage/default.jpg'
2018-01-08 20:09:04,081 [Thread-12:140670808180480] [django.request:170] [base:get_response] [WARNING]- Not Found: /quantization/inde/
2018-01-08 20:09:07,579 [Thread-13:140670808180480] [django.request:256] [base:handle_uncaught_exception] [ERROR]- Internal Server Error: /quantization/index/
Traceback (most recent call last):
  File "/root/.virtualenvs/student/lib/python3.5/site-packages/django/core/handlers/base.py", line 132, in get_response
    response = wrapped_callback(request, *callback_args, **callback_kwargs)
  File "/root/student/quantization/views.py", line 30, in index
    return render(request, 'quantization/signature.html')
  File "/root/.virtualenvs/student/lib/python3.5/site-packages/django/shortcuts.py", line 67, in render
    template_name, context, request=request, using=using)
  File "/root/.virtualenvs/student/lib/python3.5/site-packages/django/template/loader.py", line 98, in render_to_string
    template = get_template(template_name, using=using)
  File "/root/.virtualenvs/student/lib/python3.5/site-packages/django/template/loader.py", line 46, in get_template
    raise TemplateDoesNotExist(template_name)
django.template.base.TemplateDoesNotExist: quantization/signature.html
2018-01-08 20:09:18,693 [Thread-14:140670808180480] [django.request:170] [base:get_response] [WARNING]- Not Found: /user/login/
2018-01-08 20:10:13,855 [Thread-2:140189074716416] [django.request:256] [base:handle_uncaught_exception] [ERROR]- Internal Server Error: /quantization/index2/
Traceback (most recent call last):
  File "/root/.virtualenvs/student/lib/python3.5/site-packages/django/core/handlers/base.py", line 132, in get_response
    response = wrapped_callback(request, *callback_args, **callback_kwargs)
  File "/root/student/quantization/views.py", line 26, in index2
    return render(request, 'quantization/index2.html')
  File "/root/.virtualenvs/student/lib/python3.5/site-packages/django/shortcuts.py", line 67, in render
    template_name, context, request=request, using=using)
  File "/root/.virtualenvs/student/lib/python3.5/site-packages/django/template/loader.py", line 98, in render_to_string
    template = get_template(template_name, using=using)
  File "/root/.virtualenvs/student/lib/python3.5/site-packages/django/template/loader.py", line 46, in get_template
    raise TemplateDoesNotExist(template_name)
django.template.base.TemplateDoesNotExist: quantization/index2.html
2018-01-08 20:18:23,347 [Thread-2:140086411159296] [django.request:256] [base:handle_uncaught_exception] [ERROR]- Internal Server Error: /quantization/main/
Traceback (most recent call last):
  File "/root/.virtualenvs/student/lib/python3.5/site-packages/django/core/urlresolvers.py", line 394, in urlconf_module
    return self._urlconf_module
AttributeError: 'RegexURLResolver' object has no attribute '_urlconf_module'

During handling of the above exception, another exception occurred:

Traceback (most recent call last):
  File "/root/.virtualenvs/student/lib/python3.5/site-packages/django/core/handlers/base.py", line 119, in get_response
    resolver_match = resolver.resolve(request.path_info)
  File "/root/.virtualenvs/student/lib/python3.5/site-packages/django/core/urlresolvers.py", line 366, in resolve
    for pattern in self.url_patterns:
  File "/root/.virtualenvs/student/lib/python3.5/site-packages/django/core/urlresolvers.py", line 402, in url_patterns
    patterns = getattr(self.urlconf_module, "urlpatterns", self.urlconf_module)
  File "/root/.virtualenvs/student/lib/python3.5/site-packages/django/core/urlresolvers.py", line 396, in urlconf_module
    self._urlconf_module = import_module(self.urlconf_name)
  File "/root/.virtualenvs/student/lib/python3.5/importlib/__init__.py", line 126, in import_module
    return _bootstrap._gcd_import(name[level:], package, level)
  File "<frozen importlib._bootstrap>", line 986, in _gcd_import
  File "<frozen importlib._bootstrap>", line 969, in _find_and_load
  File "<frozen importlib._bootstrap>", line 958, in _find_and_load_unlocked
  File "<frozen importlib._bootstrap>", line 673, in _load_unlocked
  File "<frozen importlib._bootstrap_external>", line 665, in exec_module
  File "<frozen importlib._bootstrap>", line 222, in _call_with_frames_removed
  File "/root/student/student/urls.py", line 22, in <module>
    url(r'^quantization/', include('quantization.urls', namespace='quantization')),
  File "/root/.virtualenvs/student/lib/python3.5/site-packages/django/conf/urls/__init__.py", line 33, in include
    urlconf_module = import_module(urlconf_module)
  File "/root/.virtualenvs/student/lib/python3.5/importlib/__init__.py", line 126, in import_module
    return _bootstrap._gcd_import(name[level:], package, level)
  File "<frozen importlib._bootstrap>", line 986, in _gcd_import
  File "<frozen importlib._bootstrap>", line 969, in _find_and_load
  File "<frozen importlib._bootstrap>", line 958, in _find_and_load_unlocked
  File "<frozen importlib._bootstrap>", line 673, in _load_unlocked
  File "<frozen importlib._bootstrap_external>", line 665, in exec_module
  File "<frozen importlib._bootstrap>", line 222, in _call_with_frames_removed
  File "/root/student/quantization/urls.py", line 28, in <module>
    url(r'^index2/$', views.index2, name='index2'),
AttributeError: module 'quantization.views' has no attribute 'index2'
2018-01-08 20:18:25,612 [Thread-3:140086411159296] [django.request:256] [base:handle_uncaught_exception] [ERROR]- Internal Server Error: /quantization/common/
Traceback (most recent call last):
  File "/root/.virtualenvs/student/lib/python3.5/site-packages/django/core/urlresolvers.py", line 394, in urlconf_module
    return self._urlconf_module
AttributeError: 'RegexURLResolver' object has no attribute '_urlconf_module'

During handling of the above exception, another exception occurred:

Traceback (most recent call last):
  File "/root/.virtualenvs/student/lib/python3.5/site-packages/django/core/handlers/base.py", line 119, in get_response
    resolver_match = resolver.resolve(request.path_info)
  File "/root/.virtualenvs/student/lib/python3.5/site-packages/django/core/urlresolvers.py", line 366, in resolve
    for pattern in self.url_patterns:
  File "/root/.virtualenvs/student/lib/python3.5/site-packages/django/core/urlresolvers.py", line 402, in url_patterns
    patterns = getattr(self.urlconf_module, "urlpatterns", self.urlconf_module)
  File "/root/.virtualenvs/student/lib/python3.5/site-packages/django/core/urlresolvers.py", line 396, in urlconf_module
    self._urlconf_module = import_module(self.urlconf_name)
  File "/root/.virtualenvs/student/lib/python3.5/importlib/__init__.py", line 126, in import_module
    return _bootstrap._gcd_import(name[level:], package, level)
  File "<frozen importlib._bootstrap>", line 986, in _gcd_import
  File "<frozen importlib._bootstrap>", line 969, in _find_and_load
  File "<frozen importlib._bootstrap>", line 958, in _find_and_load_unlocked
  File "<frozen importlib._bootstrap>", line 673, in _load_unlocked
  File "<frozen importlib._bootstrap_external>", line 665, in exec_module
  File "<frozen importlib._bootstrap>", line 222, in _call_with_frames_removed
  File "/root/student/student/urls.py", line 22, in <module>
    url(r'^quantization/', include('quantization.urls', namespace='quantization')),
  File "/root/.virtualenvs/student/lib/python3.5/site-packages/django/conf/urls/__init__.py", line 33, in include
    urlconf_module = import_module(urlconf_module)
  File "/root/.virtualenvs/student/lib/python3.5/importlib/__init__.py", line 126, in import_module
    return _bootstrap._gcd_import(name[level:], package, level)
  File "<frozen importlib._bootstrap>", line 986, in _gcd_import
  File "<frozen importlib._bootstrap>", line 969, in _find_and_load
  File "<frozen importlib._bootstrap>", line 958, in _find_and_load_unlocked
  File "<frozen importlib._bootstrap>", line 673, in _load_unlocked
  File "<frozen importlib._bootstrap_external>", line 665, in exec_module
  File "<frozen importlib._bootstrap>", line 222, in _call_with_frames_removed
  File "/root/student/quantization/urls.py", line 28, in <module>
    url(r'^index2/$', views.index2, name='index2'),
AttributeError: module 'quantization.views' has no attribute 'index2'
2018-01-08 20:18:28,114 [Thread-4:140086411159296] [django.request:256] [base:handle_uncaught_exception] [ERROR]- Internal Server Error: /democratic/main/
Traceback (most recent call last):
  File "/root/.virtualenvs/student/lib/python3.5/site-packages/django/core/urlresolvers.py", line 394, in urlconf_module
    return self._urlconf_module
AttributeError: 'RegexURLResolver' object has no attribute '_urlconf_module'

During handling of the above exception, another exception occurred:

Traceback (most recent call last):
  File "/root/.virtualenvs/student/lib/python3.5/site-packages/django/core/handlers/base.py", line 119, in get_response
    resolver_match = resolver.resolve(request.path_info)
  File "/root/.virtualenvs/student/lib/python3.5/site-packages/django/core/urlresolvers.py", line 366, in resolve
    for pattern in self.url_patterns:
  File "/root/.virtualenvs/student/lib/python3.5/site-packages/django/core/urlresolvers.py", line 402, in url_patterns
    patterns = getattr(self.urlconf_module, "urlpatterns", self.urlconf_module)
  File "/root/.virtualenvs/student/lib/python3.5/site-packages/django/core/urlresolvers.py", line 396, in urlconf_module
    self._urlconf_module = import_module(self.urlconf_name)
  File "/root/.virtualenvs/student/lib/python3.5/importlib/__init__.py", line 126, in import_module
    return _bootstrap._gcd_import(name[level:], package, level)
  File "<frozen importlib._bootstrap>", line 986, in _gcd_import
  File "<frozen importlib._bootstrap>", line 969, in _find_and_load
  File "<frozen importlib._bootstrap>", line 958, in _find_and_load_unlocked
  File "<frozen importlib._bootstrap>", line 673, in _load_unlocked
  File "<frozen importlib._bootstrap_external>", line 665, in exec_module
  File "<frozen importlib._bootstrap>", line 222, in _call_with_frames_removed
  File "/root/student/student/urls.py", line 22, in <module>
    url(r'^quantization/', include('quantization.urls', namespace='quantization')),
  File "/root/.virtualenvs/student/lib/python3.5/site-packages/django/conf/urls/__init__.py", line 33, in include
    urlconf_module = import_module(urlconf_module)
  File "/root/.virtualenvs/student/lib/python3.5/importlib/__init__.py", line 126, in import_module
    return _bootstrap._gcd_import(name[level:], package, level)
  File "<frozen importlib._bootstrap>", line 986, in _gcd_import
  File "<frozen importlib._bootstrap>", line 969, in _find_and_load
  File "<frozen importlib._bootstrap>", line 958, in _find_and_load_unlocked
  File "<frozen importlib._bootstrap>", line 673, in _load_unlocked
  File "<frozen importlib._bootstrap_external>", line 665, in exec_module
  File "<frozen importlib._bootstrap>", line 222, in _call_with_frames_removed
  File "/root/student/quantization/urls.py", line 28, in <module>
    url(r'^index2/$', views.index2, name='index2'),
AttributeError: module 'quantization.views' has no attribute 'index2'
2018-01-08 20:18:29,046 [Thread-5:140086411159296] [django.request:256] [base:handle_uncaught_exception] [ERROR]- Internal Server Error: /quantization/main/
Traceback (most recent call last):
  File "/root/.virtualenvs/student/lib/python3.5/site-packages/django/core/urlresolvers.py", line 394, in urlconf_module
    return self._urlconf_module
AttributeError: 'RegexURLResolver' object has no attribute '_urlconf_module'

During handling of the above exception, another exception occurred:

Traceback (most recent call last):
  File "/root/.virtualenvs/student/lib/python3.5/site-packages/django/core/handlers/base.py", line 119, in get_response
    resolver_match = resolver.resolve(request.path_info)
  File "/root/.virtualenvs/student/lib/python3.5/site-packages/django/core/urlresolvers.py", line 366, in resolve
    for pattern in self.url_patterns:
  File "/root/.virtualenvs/student/lib/python3.5/site-packages/django/core/urlresolvers.py", line 402, in url_patterns
    patterns = getattr(self.urlconf_module, "urlpatterns", self.urlconf_module)
  File "/root/.virtualenvs/student/lib/python3.5/site-packages/django/core/urlresolvers.py", line 396, in urlconf_module
    self._urlconf_module = import_module(self.urlconf_name)
  File "/root/.virtualenvs/student/lib/python3.5/importlib/__init__.py", line 126, in import_module
    return _bootstrap._gcd_import(name[level:], package, level)
  File "<frozen importlib._bootstrap>", line 986, in _gcd_import
  File "<frozen importlib._bootstrap>", line 969, in _find_and_load
  File "<frozen importlib._bootstrap>", line 958, in _find_and_load_unlocked
  File "<frozen importlib._bootstrap>", line 673, in _load_unlocked
  File "<frozen importlib._bootstrap_external>", line 665, in exec_module
  File "<frozen importlib._bootstrap>", line 222, in _call_with_frames_removed
  File "/root/student/student/urls.py", line 22, in <module>
    url(r'^quantization/', include('quantization.urls', namespace='quantization')),
  File "/root/.virtualenvs/student/lib/python3.5/site-packages/django/conf/urls/__init__.py", line 33, in include
    urlconf_module = import_module(urlconf_module)
  File "/root/.virtualenvs/student/lib/python3.5/importlib/__init__.py", line 126, in import_module
    return _bootstrap._gcd_import(name[level:], package, level)
  File "<frozen importlib._bootstrap>", line 986, in _gcd_import
  File "<frozen importlib._bootstrap>", line 969, in _find_and_load
  File "<frozen importlib._bootstrap>", line 958, in _find_and_load_unlocked
  File "<frozen importlib._bootstrap>", line 673, in _load_unlocked
  File "<frozen importlib._bootstrap_external>", line 665, in exec_module
  File "<frozen importlib._bootstrap>", line 222, in _call_with_frames_removed
  File "/root/student/quantization/urls.py", line 28, in <module>
    url(r'^index2/$', views.index2, name='index2'),
AttributeError: module 'quantization.views' has no attribute 'index2'
2018-01-08 20:18:56,904 [Thread-2:140164121106176] [django.request:170] [base:get_response] [WARNING]- Not Found: /quantization/main/
2018-01-08 20:19:06,902 [Thread-3:140164121106176] [django.request:256] [base:handle_uncaught_exception] [ERROR]- Internal Server Error: /quantization/test/
Traceback (most recent call last):
  File "/root/.virtualenvs/student/lib/python3.5/site-packages/django/core/handlers/base.py", line 132, in get_response
    response = wrapped_callback(request, *callback_args, **callback_kwargs)
  File "/root/student/quantization/views.py", line 12, in test
    return render(request, 'quantization/test.html')
  File "/root/.virtualenvs/student/lib/python3.5/site-packages/django/shortcuts.py", line 67, in render
    template_name, context, request=request, using=using)
  File "/root/.virtualenvs/student/lib/python3.5/site-packages/django/template/loader.py", line 98, in render_to_string
    template = get_template(template_name, using=using)
  File "/root/.virtualenvs/student/lib/python3.5/site-packages/django/template/loader.py", line 46, in get_template
    raise TemplateDoesNotExist(template_name)
django.template.base.TemplateDoesNotExist: quantization/test.html
2018-01-08 20:19:35,979 [Thread-2:139996453500672] [django.request:170] [base:get_response] [WARNING]- Not Found: /quantization/main/
2018-01-08 20:19:38,586 [Thread-6:139996442920704] [django.request:170] [base:get_response] [WARNING]- Not Found: /images/form/city.png
2018-01-08 20:19:38,642 [Thread-7:139996442920704] [django.request:170] [base:get_response] [WARNING]- Not Found: /wjx/join/UploadqiniuMobo2.aspx
2018-01-08 20:19:38,647 [Thread-8:139996453500672] [django.request:170] [base:get_response] [WARNING]- Not Found: /wjx/join/UploadqiniuMobo2.aspx
2018-01-08 20:19:38,660 [Thread-9:139996434528000] [django.request:170] [base:get_response] [WARNING]- Not Found: /wjx/join/UploadqiniuMobo2.aspx
2018-01-08 20:19:38,683 [Thread-10:139996425873152] [django.request:170] [base:get_response] [WARNING]- Not Found: /wjx/join/UploadqiniuMobo2.aspx
2018-01-08 20:20:13,300 [Thread-2:140200590628608] [django.request:170] [base:get_response] [WARNING]- Not Found: /quantization/common/
2018-01-08 20:52:51,375 [Thread-64:139822677055232] [django.request:170] [base:get_response] [WARNING]- Not Found: /quantization/main/
2018-01-08 22:13:06,376 [Thread-624:140060054951680] [django.request:170] [base:get_response] [WARNING]- Not Found: /favicon.ico
2018-01-08 22:40:36,345 [Thread-2:139828798109440] [django.request:256] [base:handle_uncaught_exception] [ERROR]- Internal Server Error: /quantization/index/
Traceback (most recent call last):
  File "/root/.virtualenvs/student/lib/python3.5/site-packages/django/core/urlresolvers.py", line 394, in urlconf_module
    return self._urlconf_module
AttributeError: 'RegexURLResolver' object has no attribute '_urlconf_module'

During handling of the above exception, another exception occurred:

Traceback (most recent call last):
  File "/root/.virtualenvs/student/lib/python3.5/site-packages/django/core/handlers/base.py", line 119, in get_response
    resolver_match = resolver.resolve(request.path_info)
  File "/root/.virtualenvs/student/lib/python3.5/site-packages/django/core/urlresolvers.py", line 366, in resolve
    for pattern in self.url_patterns:
  File "/root/.virtualenvs/student/lib/python3.5/site-packages/django/core/urlresolvers.py", line 402, in url_patterns
    patterns = getattr(self.urlconf_module, "urlpatterns", self.urlconf_module)
  File "/root/.virtualenvs/student/lib/python3.5/site-packages/django/core/urlresolvers.py", line 396, in urlconf_module
    self._urlconf_module = import_module(self.urlconf_name)
  File "/root/.virtualenvs/student/lib/python3.5/importlib/__init__.py", line 126, in import_module
    return _bootstrap._gcd_import(name[level:], package, level)
  File "<frozen importlib._bootstrap>", line 986, in _gcd_import
  File "<frozen importlib._bootstrap>", line 969, in _find_and_load
  File "<frozen importlib._bootstrap>", line 958, in _find_and_load_unlocked
  File "<frozen importlib._bootstrap>", line 673, in _load_unlocked
  File "<frozen importlib._bootstrap_external>", line 665, in exec_module
  File "<frozen importlib._bootstrap>", line 222, in _call_with_frames_removed
  File "/root/student/student/urls.py", line 22, in <module>
    url(r'^quantization/', include('quantization.urls', namespace='quantization')),
  File "/root/.virtualenvs/student/lib/python3.5/site-packages/django/conf/urls/__init__.py", line 33, in include
    urlconf_module = import_module(urlconf_module)
  File "/root/.virtualenvs/student/lib/python3.5/importlib/__init__.py", line 126, in import_module
    return _bootstrap._gcd_import(name[level:], package, level)
  File "<frozen importlib._bootstrap>", line 986, in _gcd_import
  File "<frozen importlib._bootstrap>", line 969, in _find_and_load
  File "<frozen importlib._bootstrap>", line 958, in _find_and_load_unlocked
  File "<frozen importlib._bootstrap>", line 673, in _load_unlocked
  File "<frozen importlib._bootstrap_external>", line 665, in exec_module
  File "<frozen importlib._bootstrap>", line 222, in _call_with_frames_removed
  File "/root/student/quantization/urls.py", line 18, in <module>
    from . import views
  File "/root/student/quantization/views.py", line 30
    < QueryDict: {'clazz': ['软件技术1611'], 'nation': ['汉族'], 'department': ['计算机工程系'], 'studentId': ['123'],
    ^
SyntaxError: invalid syntax
2018-01-08 22:40:38,801 [Thread-3:139828798109440] [django.request:256] [base:handle_uncaught_exception] [ERROR]- Internal Server Error: /quantization/index/
Traceback (most recent call last):
  File "/root/.virtualenvs/student/lib/python3.5/site-packages/django/core/urlresolvers.py", line 394, in urlconf_module
    return self._urlconf_module
AttributeError: 'RegexURLResolver' object has no attribute '_urlconf_module'

During handling of the above exception, another exception occurred:

Traceback (most recent call last):
  File "/root/.virtualenvs/student/lib/python3.5/site-packages/django/core/handlers/base.py", line 119, in get_response
    resolver_match = resolver.resolve(request.path_info)
  File "/root/.virtualenvs/student/lib/python3.5/site-packages/django/core/urlresolvers.py", line 366, in resolve
    for pattern in self.url_patterns:
  File "/root/.virtualenvs/student/lib/python3.5/site-packages/django/core/urlresolvers.py", line 402, in url_patterns
    patterns = getattr(self.urlconf_module, "urlpatterns", self.urlconf_module)
  File "/root/.virtualenvs/student/lib/python3.5/site-packages/django/core/urlresolvers.py", line 396, in urlconf_module
    self._urlconf_module = import_module(self.urlconf_name)
  File "/root/.virtualenvs/student/lib/python3.5/importlib/__init__.py", line 126, in import_module
    return _bootstrap._gcd_import(name[level:], package, level)
  File "<frozen importlib._bootstrap>", line 986, in _gcd_import
  File "<frozen importlib._bootstrap>", line 969, in _find_and_load
  File "<frozen importlib._bootstrap>", line 958, in _find_and_load_unlocked
  File "<frozen importlib._bootstrap>", line 673, in _load_unlocked
  File "<frozen importlib._bootstrap_external>", line 665, in exec_module
  File "<frozen importlib._bootstrap>", line 222, in _call_with_frames_removed
  File "/root/student/student/urls.py", line 22, in <module>
    url(r'^quantization/', include('quantization.urls', namespace='quantization')),
  File "/root/.virtualenvs/student/lib/python3.5/site-packages/django/conf/urls/__init__.py", line 33, in include
    urlconf_module = import_module(urlconf_module)
  File "/root/.virtualenvs/student/lib/python3.5/importlib/__init__.py", line 126, in import_module
    return _bootstrap._gcd_import(name[level:], package, level)
  File "<frozen importlib._bootstrap>", line 986, in _gcd_import
  File "<frozen importlib._bootstrap>", line 969, in _find_and_load
  File "<frozen importlib._bootstrap>", line 958, in _find_and_load_unlocked
  File "<frozen importlib._bootstrap>", line 673, in _load_unlocked
  File "<frozen importlib._bootstrap_external>", line 665, in exec_module
  File "<frozen importlib._bootstrap>", line 222, in _call_with_frames_removed
  File "/root/student/quantization/urls.py", line 18, in <module>
    from . import views
  File "/root/student/quantization/views.py", line 30
    < QueryDict: {'clazz': ['软件技术1611'], 'nation': ['汉族'], 'department': ['计算机工程系'], 'studentId': ['123'],
    ^
SyntaxError: invalid syntax
2018-01-08 22:49:25,597 [Thread-19:139828549113600] [django.request:256] [base:handle_uncaught_exception] [ERROR]- Internal Server Error: /quantization/index_handler/
Traceback (most recent call last):
  File "/root/.virtualenvs/student/lib/python3.5/site-packages/django/core/handlers/base.py", line 132, in get_response
    response = wrapped_callback(request, *callback_args, **callback_kwargs)
  File "/root/.virtualenvs/student/lib/python3.5/site-packages/django/views/decorators/csrf.py", line 58, in wrapped_view
    return view_func(*args, **kwargs)
  File "/root/student/quantization/views.py", line 29, in index_handler
    gender=gender, major=major, id=sid)
  File "/root/.virtualenvs/student/lib/python3.5/site-packages/django/db/models/base.py", line 480, in __init__
    raise TypeError("'%s' is an invalid keyword argument for this function" % list(kwargs)[0])
TypeError: 'id' is an invalid keyword argument for this function
2018-01-08 22:50:38,378 [Thread-20:139828549113600] [django.request:256] [base:handle_uncaught_exception] [ERROR]- Internal Server Error: /quantization/index_handler/
Traceback (most recent call last):
  File "/root/.virtualenvs/student/lib/python3.5/site-packages/django/core/handlers/base.py", line 132, in get_response
    response = wrapped_callback(request, *callback_args, **callback_kwargs)
  File "/root/.virtualenvs/student/lib/python3.5/site-packages/django/views/decorators/csrf.py", line 58, in wrapped_view
    return view_func(*args, **kwargs)
  File "/root/student/quantization/views.py", line 29, in index_handler
    gender=gender, major=major, id=sid)
  File "/root/.virtualenvs/student/lib/python3.5/site-packages/django/db/models/base.py", line 480, in __init__
    raise TypeError("'%s' is an invalid keyword argument for this function" % list(kwargs)[0])
TypeError: 'id' is an invalid keyword argument for this function
2018-01-08 22:57:26,056 [Thread-32:140115609822976] [django.request:256] [base:handle_uncaught_exception] [ERROR]- Internal Server Error: /quantization/index_handler/
Traceback (most recent call last):
  File "/root/.virtualenvs/student/lib/python3.5/site-packages/django/core/handlers/base.py", line 132, in get_response
    response = wrapped_callback(request, *callback_args, **callback_kwargs)
  File "/root/.virtualenvs/student/lib/python3.5/site-packages/django/views/decorators/csrf.py", line 58, in wrapped_view
    return view_func(*args, **kwargs)
  File "/root/student/quantization/views.py", line 35, in index_handler
    print(sid)
NameError: name 'sid' is not defined
2018-01-08 22:59:34,624 [Thread-51:140605812369152] [django.request:170] [base:get_response] [WARNING]- Not Found: /media/studentDatum/1.png
2018-01-15 11:05:34,071 [Thread-19:140110174603008] [django.request:170] [base:get_response] [WARNING]- Not Found: /favicon.ico
2018-01-15 15:48:31,507 [Thread-642:140109936580352] [django.request:170] [base:get_response] [WARNING]- Not Found: /user/login/
2018-01-15 17:14:43,467 [Thread-26:139806362388224] [django.request:170] [base:get_response] [WARNING]- Not Found: /favicon.ico
2018-01-15 18:16:06,026 [Thread-23:140167045351168] [django.request:256] [base:handle_uncaught_exception] [ERROR]- Internal Server Error: /quantization/uploadimg/
Traceback (most recent call last):
  File "/root/.virtualenvs/student/lib/python3.5/site-packages/django/core/handlers/base.py", line 132, in get_response
    response = wrapped_callback(request, *callback_args, **callback_kwargs)
  File "/root/.virtualenvs/student/lib/python3.5/site-packages/django/views/decorators/csrf.py", line 58, in wrapped_view
    return view_func(*args, **kwargs)
  File "/root/student/quantization/views.py", line 75, in uploadimg
    print(img.name)
AttributeError: 'tuple' object has no attribute 'name'
2018-01-15 19:29:13,764 [Thread-23:139791395989248] [django.request:256] [base:handle_uncaught_exception] [ERROR]- Internal Server Error: /quantization/uploadimg/
Traceback (most recent call last):
  File "/root/.virtualenvs/student/lib/python3.5/site-packages/django/core/handlers/base.py", line 223, in get_response
    response = middleware_method(request, response)
  File "/root/.virtualenvs/student/lib/python3.5/site-packages/django/middleware/clickjacking.py", line 31, in process_response
    if response.get('X-Frame-Options', None) is not None:
AttributeError: 'str' object has no attribute 'get'
2018-01-15 19:33:16,110 [Thread-31:139639398323968] [django.request:256] [base:handle_uncaught_exception] [ERROR]- Internal Server Error: /quantization/uploadimg/
Traceback (most recent call last):
  File "/root/.virtualenvs/student/lib/python3.5/site-packages/django/core/handlers/base.py", line 132, in get_response
    response = wrapped_callback(request, *callback_args, **callback_kwargs)
  File "/root/.virtualenvs/student/lib/python3.5/site-packages/django/views/decorators/csrf.py", line 58, in wrapped_view
    return view_func(*args, **kwargs)
  File "/root/student/quantization/views.py", line 85, in uploadimg
    studentId=StudentInfo.objects.get(studentId="2016010978")
  File "/root/.virtualenvs/student/lib/python3.5/site-packages/django/db/models/manager.py", line 127, in manager_method
    return getattr(self.get_queryset(), name)(*args, **kwargs)
  File "/root/.virtualenvs/student/lib/python3.5/site-packages/django/db/models/query.py", line 334, in get
    self.model._meta.object_name
quantization.models.DoesNotExist: StudentInfo matching query does not exist.
2018-01-15 19:33:57,473 [Thread-34:139639398323968] [django.request:256] [base:handle_uncaught_exception] [ERROR]- Internal Server Error: /quantization/uploadimg/
Traceback (most recent call last):
  File "/root/.virtualenvs/student/lib/python3.5/site-packages/django/core/handlers/base.py", line 132, in get_response
    response = wrapped_callback(request, *callback_args, **callback_kwargs)
  File "/root/.virtualenvs/student/lib/python3.5/site-packages/django/views/decorators/csrf.py", line 58, in wrapped_view
    return view_func(*args, **kwargs)
  File "/root/student/quantization/views.py", line 85, in uploadimg
    studentId=StudentInfo.objects.get(studentId="2016010978")
  File "/root/.virtualenvs/student/lib/python3.5/site-packages/django/db/models/manager.py", line 127, in manager_method
    return getattr(self.get_queryset(), name)(*args, **kwargs)
  File "/root/.virtualenvs/student/lib/python3.5/site-packages/django/db/models/query.py", line 334, in get
    self.model._meta.object_name
quantization.models.DoesNotExist: StudentInfo matching query does not exist.
2018-01-15 19:34:49,211 [Thread-23:140607139219200] [django.request:256] [base:handle_uncaught_exception] [ERROR]- Internal Server Error: /quantization/uploadimg/
Traceback (most recent call last):
  File "/root/.virtualenvs/student/lib/python3.5/site-packages/django/core/handlers/base.py", line 132, in get_response
    response = wrapped_callback(request, *callback_args, **callback_kwargs)
  File "/root/.virtualenvs/student/lib/python3.5/site-packages/django/views/decorators/csrf.py", line 58, in wrapped_view
    return view_func(*args, **kwargs)
  File "/root/student/quantization/views.py", line 85, in uploadimg
    studentId=StudentInfo.objects.get(studentId="2016010978")
  File "/root/.virtualenvs/student/lib/python3.5/site-packages/django/db/models/manager.py", line 127, in manager_method
    return getattr(self.get_queryset(), name)(*args, **kwargs)
  File "/root/.virtualenvs/student/lib/python3.5/site-packages/django/db/models/query.py", line 334, in get
    self.model._meta.object_name
quantization.models.DoesNotExist: StudentInfo matching query does not exist.
2018-01-15 19:45:16,562 [Thread-43:140663196669696] [django.request:170] [base:get_response] [WARNING]- Not Found: /root/student/media/baseDatum/666666_baseDatum.jpg
2018-01-15 19:46:02,609 [Thread-2:140169610188544] [django.request:256] [base:handle_uncaught_exception] [ERROR]- Internal Server Error: /admin/quantization/studentanswer/12/
Traceback (most recent call last):
  File "/root/.virtualenvs/student/lib/python3.5/site-packages/django/core/urlresolvers.py", line 394, in urlconf_module
    return self._urlconf_module
AttributeError: 'RegexURLResolver' object has no attribute '_urlconf_module'

During handling of the above exception, another exception occurred:

Traceback (most recent call last):
  File "/root/.virtualenvs/student/lib/python3.5/site-packages/django/core/handlers/base.py", line 119, in get_response
    resolver_match = resolver.resolve(request.path_info)
  File "/root/.virtualenvs/student/lib/python3.5/site-packages/django/core/urlresolvers.py", line 366, in resolve
    for pattern in self.url_patterns:
  File "/root/.virtualenvs/student/lib/python3.5/site-packages/django/core/urlresolvers.py", line 402, in url_patterns
    patterns = getattr(self.urlconf_module, "urlpatterns", self.urlconf_module)
  File "/root/.virtualenvs/student/lib/python3.5/site-packages/django/core/urlresolvers.py", line 396, in urlconf_module
    self._urlconf_module = import_module(self.urlconf_name)
  File "/root/.virtualenvs/student/lib/python3.5/importlib/__init__.py", line 126, in import_module
    return _bootstrap._gcd_import(name[level:], package, level)
  File "<frozen importlib._bootstrap>", line 986, in _gcd_import
  File "<frozen importlib._bootstrap>", line 969, in _find_and_load
  File "<frozen importlib._bootstrap>", line 958, in _find_and_load_unlocked
  File "<frozen importlib._bootstrap>", line 673, in _load_unlocked
  File "<frozen importlib._bootstrap_external>", line 665, in exec_module
  File "<frozen importlib._bootstrap>", line 222, in _call_with_frames_removed
  File "/root/student/student/urls.py", line 27, in <module>
    ]+ static(document_root=settings.MEDIA_ROOT)
TypeError: static() missing 1 required positional argument: 'prefix'
2018-01-15 19:46:13,918 [Thread-20:140169581774592] [django.request:170] [base:get_response] [WARNING]- Not Found: /root/student/media/baseDatum/666666_baseDatum.jpg
2018-01-15 19:46:24,825 [Thread-2:139957328246528] [django.request:170] [base:get_response] [WARNING]- Not Found: /root/student/media/baseDatum/666666_baseDatum.jpg
2018-01-15 19:46:27,663 [Thread-20:139957308225280] [django.request:170] [base:get_response] [WARNING]- Not Found: /root/student/media/baseDatum/666666_baseDatum.jpg
