2018-01-24 20:38:30,764 [Thread-81:139693138040576] [django.request:256] [base:handle_uncaught_exception] [ERROR]- Internal Server Error: /quantization/main_handler/
Traceback (most recent call last):
  File "/root/.virtualenvs/student/lib/python3.5/site-packages/django/core/handlers/base.py", line 132, in get_response
    response = wrapped_callback(request, *callback_args, **callback_kwargs)
  File "/root/.virtualenvs/student/lib/python3.5/site-packages/django/views/decorators/csrf.py", line 58, in wrapped_view
    return view_func(*args, **kwargs)
  File "/root/student/quantization/views.py", line 75, in main_handler
    StudentAnswer.objects.create(**data)
  File "/root/.virtualenvs/student/lib/python3.5/site-packages/django/db/models/manager.py", line 127, in manager_method
    return getattr(self.get_queryset(), name)(*args, **kwargs)
  File "/root/.virtualenvs/student/lib/python3.5/site-packages/django/db/models/query.py", line 346, in create
    obj = self.model(**kwargs)
  File "/root/.virtualenvs/student/lib/python3.5/site-packages/django/db/models/base.py", line 468, in __init__
    setattr(self, field.name, rel_obj)
  File "/root/.virtualenvs/student/lib/python3.5/site-packages/django/db/models/fields/related.py", line 635, in __set__
    self.field.rel.to._meta.object_name,
ValueError: Cannot assign "'3'": "StudentAnswer.studentId" must be a "StudentInfo" instance.
2018-01-24 20:39:07,180 [Thread-82:139693138040576] [django.request:170] [base:get_response] [WARNING]- Not Found: /user/login/
2018-01-24 20:39:34,488 [Thread-90:139693138040576] [django.request:256] [base:handle_uncaught_exception] [ERROR]- Internal Server Error: /quantization/main_handler/
Traceback (most recent call last):
  File "/root/.virtualenvs/student/lib/python3.5/site-packages/django/core/handlers/base.py", line 132, in get_response
    response = wrapped_callback(request, *callback_args, **callback_kwargs)
  File "/root/.virtualenvs/student/lib/python3.5/site-packages/django/views/decorators/csrf.py", line 58, in wrapped_view
    return view_func(*args, **kwargs)
  File "/root/student/quantization/views.py", line 75, in main_handler
    StudentAnswer.objects.create(**data)
  File "/root/.virtualenvs/student/lib/python3.5/site-packages/django/db/models/manager.py", line 127, in manager_method
    return getattr(self.get_queryset(), name)(*args, **kwargs)
  File "/root/.virtualenvs/student/lib/python3.5/site-packages/django/db/models/query.py", line 346, in create
    obj = self.model(**kwargs)
  File "/root/.virtualenvs/student/lib/python3.5/site-packages/django/db/models/base.py", line 468, in __init__
    setattr(self, field.name, rel_obj)
  File "/root/.virtualenvs/student/lib/python3.5/site-packages/django/db/models/fields/related.py", line 635, in __set__
    self.field.rel.to._meta.object_name,
ValueError: Cannot assign "'3'": "StudentAnswer.studentId" must be a "StudentInfo" instance.
2018-01-24 20:44:31,649 [Thread-2:140449713133312] [django.request:256] [base:handle_uncaught_exception] [ERROR]- Internal Server Error: /quantization/main_handler/
Traceback (most recent call last):
  File "/root/.virtualenvs/student/lib/python3.5/site-packages/django/core/handlers/base.py", line 132, in get_response
    response = wrapped_callback(request, *callback_args, **callback_kwargs)
  File "/root/.virtualenvs/student/lib/python3.5/site-packages/django/views/decorators/csrf.py", line 58, in wrapped_view
    return view_func(*args, **kwargs)
  File "/root/student/quantization/views.py", line 75, in main_handler
    StudentAnswer.objects.create(pk=studentId, **data)
  File "/root/.virtualenvs/student/lib/python3.5/site-packages/django/db/models/manager.py", line 127, in manager_method
    return getattr(self.get_queryset(), name)(*args, **kwargs)
  File "/root/.virtualenvs/student/lib/python3.5/site-packages/django/db/models/query.py", line 346, in create
    obj = self.model(**kwargs)
  File "/root/.virtualenvs/student/lib/python3.5/site-packages/django/db/models/base.py", line 468, in __init__
    setattr(self, field.name, rel_obj)
  File "/root/.virtualenvs/student/lib/python3.5/site-packages/django/db/models/fields/related.py", line 635, in __set__
    self.field.rel.to._meta.object_name,
ValueError: Cannot assign "'3'": "StudentAnswer.studentId" must be a "StudentInfo" instance.
2018-01-24 20:55:45,313 [Thread-2:140638972540672] [django.request:256] [base:handle_uncaught_exception] [ERROR]- Internal Server Error: /quantization/main_handler/
Traceback (most recent call last):
  File "/root/.virtualenvs/student/lib/python3.5/site-packages/django/core/handlers/base.py", line 132, in get_response
    response = wrapped_callback(request, *callback_args, **callback_kwargs)
  File "/root/.virtualenvs/student/lib/python3.5/site-packages/django/views/decorators/csrf.py", line 58, in wrapped_view
    return view_func(*args, **kwargs)
  File "/root/student/quantization/views.py", line 75, in main_handler
    StudentAnswer.objects.create(pk=StudentInfo.objects.get(studentId=studentId), **data)
  File "/root/.virtualenvs/student/lib/python3.5/site-packages/django/db/models/manager.py", line 127, in manager_method
    return getattr(self.get_queryset(), name)(*args, **kwargs)
  File "/root/.virtualenvs/student/lib/python3.5/site-packages/django/db/models/query.py", line 346, in create
    obj = self.model(**kwargs)
  File "/root/.virtualenvs/student/lib/python3.5/site-packages/django/db/models/base.py", line 468, in __init__
    setattr(self, field.name, rel_obj)
  File "/root/.virtualenvs/student/lib/python3.5/site-packages/django/db/models/fields/related.py", line 635, in __set__
    self.field.rel.to._meta.object_name,
ValueError: Cannot assign "'3'": "StudentAnswer.studentId" must be a "StudentInfo" instance.
2018-01-24 20:56:22,695 [Thread-2:140079553050368] [django.request:256] [base:handle_uncaught_exception] [ERROR]- Internal Server Error: /quantization/main_handler/
Traceback (most recent call last):
  File "/root/.virtualenvs/student/lib/python3.5/site-packages/django/core/handlers/base.py", line 132, in get_response
    response = wrapped_callback(request, *callback_args, **callback_kwargs)
  File "/root/.virtualenvs/student/lib/python3.5/site-packages/django/views/decorators/csrf.py", line 58, in wrapped_view
    return view_func(*args, **kwargs)
  File "/root/student/quantization/views.py", line 75, in main_handler
    StudentAnswer.objects.create(studentId=StudentInfo.objects.get(studentId=studentId), **data)
TypeError: create() got multiple values for keyword argument 'studentId'
2018-01-24 20:59:19,487 [Thread-2:139807335388928] [django.request:256] [base:handle_uncaught_exception] [ERROR]- Internal Server Error: /quantization/main_handler/
Traceback (most recent call last):
  File "/root/.virtualenvs/student/lib/python3.5/site-packages/django/db/models/options.py", line 552, in get_field
    return self.fields_map[field_name]
KeyError: 'zcdd'

During handling of the above exception, another exception occurred:

Traceback (most recent call last):
  File "/root/.virtualenvs/student/lib/python3.5/site-packages/django/core/handlers/base.py", line 132, in get_response
    response = wrapped_callback(request, *callback_args, **callback_kwargs)
  File "/root/.virtualenvs/student/lib/python3.5/site-packages/django/views/decorators/csrf.py", line 58, in wrapped_view
    return view_func(*args, **kwargs)
  File "/root/student/quantization/views.py", line 79, in main_handler
    StudentAnswer.objects.update(**data)
  File "/root/.virtualenvs/student/lib/python3.5/site-packages/django/db/models/manager.py", line 127, in manager_method
    return getattr(self.get_queryset(), name)(*args, **kwargs)
  File "/root/.virtualenvs/student/lib/python3.5/site-packages/django/db/models/query.py", line 561, in update
    query.add_update_values(kwargs)
  File "/root/.virtualenvs/student/lib/python3.5/site-packages/django/db/models/sql/subqueries.py", line 122, in add_update_values
    field = self.get_meta().get_field(name)
  File "/root/.virtualenvs/student/lib/python3.5/site-packages/django/db/models/options.py", line 554, in get_field
    raise FieldDoesNotExist('%s has no field named %r' % (self.object_name, field_name))
django.core.exceptions.FieldDoesNotExist: StudentAnswer has no field named 'zcdd'
2018-01-25 10:50:45,279 [Thread-2:140032004032256] [django.request:170] [base:get_response] [WARNING]- Not Found: /user/login/
2018-01-25 10:50:45,432 [Thread-3:140032004032256] [django.request:170] [base:get_response] [WARNING]- Not Found: /favicon.ico
2018-01-25 10:55:36,108 [Thread-109:140031984797440] [django.request:170] [base:get_response] [WARNING]- Not Found: /user/login/
2018-01-25 14:43:59,424 [Thread-29:139739237185280] [django.request:170] [base:get_response] [WARNING]- Not Found: /admin/theme/data
